Workbook

Sheet CONG_VIEC
A1: SỔ CÔNG VIỆC — NƠI NHẬP LIỆU DUY NHẤT (tối đa 300 việc)
A2: Ô nền VÀNG: anh nhập. Ô nền XÁM: tự tính, không sửa. Các sheet khác tự cập nhật từ đây.
A3: 5 dòng [VÍ DỤ] chỉ để minh họa cách nhập — xóa nội dung các ô vàng của chúng trước khi dùng thật.
S4: Cột phụ cho các sheet xem (không sửa)
A5: Mã việc | B5: Ngày giao | C5: Tên công việc | D5: Đơn vị | E5: Phường / địa bàn | F5: Người phụ trách | G5: Nguồn việc | H5: Quan trọng? | I5: Khẩn cấp? | J5: Hạn hoàn thành | K5: Trạng thái | L5: Ngày hoàn thành | M5: Ghi chú | N5: Nhóm ưu tiên | O5: Số ngày còn lại | P5: Tình trạng hạn | Q5: Tuần (theo hạn) | S5: k_HomNay | T5: k_ChuaLam | U5: k_DangLam | V5: k_ChoDuyet | W5: k_HoanThanh | X5: k_Q1 | Y5: k_Q2 | Z5: k_Q3 | AA5: k_Q4 | AB5: k_Tuan
A6: =IF(C6="","","CV"&TEXT(ROW()-5,"000")) -> CV001 | B6: 46278 | C6: [VÍ DỤ] Thu gom rác tồn đọng tuyến phố chính | D6: =DANH_MUC!A5 -> Đơn vị 1 (sửa tên) | E6: =DANH_MUC!B5 -> Phường 1 (sửa tên) | F6: =DANH_MUC!C5 -> Người 1 (sửa tên) | G6: Phát sinh nội bộ | H6: Có | I6: Có | J6: 46286 | K6: Đang làm | M6: Dữ liệu minh họa | N6: =IF(C6="","",IF(AND(H6="Có",I6="Có"),"1. Làm ngay",IF(H6="Có","2. Lên lịch",IF(I6="Có","3. Giao lại","4. Để sau")))) -> 1. Làm ngay | O6: =IF(OR(C6="",J6="",K6="Hoàn thành"),"",J6-TODAY()) -> -2 | P6: =IF(C6="","",IF(K6="Hoàn thành",IF(OR(L6="",J6=""),"Xong (thiếu ngày)",IF(L6<=J6,"Xong đúng hạn","Xong trễ")),IF(J6="","Chưa có hạn",IF(J6<TODAY(),"Quá hạn",IF(J6=TODAY(),"Đến hạn hôm nay",IF(J6-TODAY()<=3,"Sắp đến hạn","Trong hạn")))))) -> Quá hạn | Q6: =IF(OR(C6="",J6=""),"",WEEKNUM(J6,21)) -> 39 | S6: =IF(AND(C6<>"",K6<>"Hoàn thành",J6<>"",J6<=TODAY()),MAX(S$5:S5)+1,"") -> 1 | T6: =IF(AND(C6<>"",IF(K6="","Chưa làm",K6)="Chưa làm"),MAX(T$5:T5)+1,"") | U6: =IF(AND(C6<>"",IF(K6="","Chưa làm",K6)="Đang làm"),MAX(U$5:U5)+1,"") -> 1 | V6: =IF(AND(C6<>"",IF(K6="","Chưa làm",K6)="Chờ duyệt"),MAX(V$5:V5)+1,"") | W6: =IF(AND(C6<>"",IF(K6="","Chưa làm",K6)="Hoàn thành"),MAX(W$5:W5)+1,"") | X6: =IF(AND(C6<>"",K6<>"Hoàn thành",N6="1. Làm ngay"),MAX(X$5:X5)+1,"") -> 1 | Y6: =IF(AND(C6<>"",K6<>"Hoàn thành",N6="2. Lên lịch"),MAX(Y$5:Y5)+1,"") | Z6: =IF(AND(C6<>"",K6<>"Hoàn thành",N6="3. Giao lại"),MAX(Z$5:Z5)+1,"") | AA6: =IF(AND(C6<>"",K6<>"Hoàn thành",N6="4. Để sau"),MAX(AA$5:AA5)+1,"") | AB6: =IF(AND(C6<>"",J6<>"",J6>=TUAN!$C$3,J6<=TUAN!$C$3+6),MAX(AB$5:AB5)+1,"") -> 1
A7: =IF(C7="","","CV"&TEXT(ROW()-5,"000")) -> CV002 | B7: 46283 | C7: [VÍ DỤ] Báo cáo tiến độ vệ sinh môi trường tháng 9 | D7: =DANH_MUC!A6 -> Đơn vị 2 (sửa tên) | F7: =DANH_MUC!C6 -> Người 2 (sửa tên) | G7: Cấp trên giao | H7: Có | I7: Có | J7: 46288 | K7: Chưa làm | M7: Dữ liệu minh họa | N7: =IF(C7="","",IF(AND(H7="Có",I7="Có"),"1. Làm ngay",IF(H7="Có","2. Lên lịch",IF(I7="Có","3. Giao lại","4. Để sau")))) -> 1. Làm ngay | O7: =IF(OR(C7="",J7="",K7="Hoàn thành"),"",J7-TODAY()) -> 0 | P7: =IF(C7="","",IF(K7="Hoàn thành",IF(OR(L7="",J7=""),"Xong (thiếu ngày)",IF(L7<=J7,"Xong đúng hạn","Xong trễ")),IF(J7="","Chưa có hạn",IF(J7<TODAY(),"Quá hạn",IF(J7=TODAY(),"Đến hạn hôm nay",IF(J7-TODAY()<=3,"Sắp đến hạn","Trong hạn")))))) -> Đến hạn hôm nay | Q7: =IF(OR(C7="",J7=""),"",WEEKNUM(J7,21)) -> 39 | S7: =IF(AND(C7<>"",K7<>"Hoàn thành",J7<>"",J7<=TODAY()),MAX(S$5:S6)+1,"") -> 2 | T7: =IF(AND(C7<>"",IF(K7="","Chưa làm",K7)="Chưa làm"),MAX(T$5:T6)+1,"") -> 1 | U7: =IF(AND(C7<>"",IF(K7="","Chưa làm",K7)="Đang làm"),MAX(U$5:U6)+1,"") | V7: =IF(AND(C7<>"",IF(K7="","Chưa làm",K7)="Chờ duyệt"),MAX(V$5:V6)+1,"") | W7: =IF(AND(C7<>"",IF(K7="","Chưa làm",K7)="Hoàn thành"),MAX(W$5:W6)+1,"") | X7: =IF(AND(C7<>"",K7<>"Hoàn thành",N7="1. Làm ngay"),MAX(X$5:X6)+1,"") -> 2 | Y7: =IF(AND(C7<>"",K7<>"Hoàn thành",N7="2. Lên lịch"),MAX(Y$5:Y6)+1,"") | Z7: =IF(AND(C7<>"",K7<>"Hoàn thành",N7="3. Giao lại"),MAX(Z$5:Z6)+1,"") | AA7: =IF(AND(C7<>"",K7<>"Hoàn thành",N7="4. Để sau"),MAX(AA$5:AA6)+1,"") | AB7: =IF(AND(C7<>"",J7<>"",J7>=TUAN!$C$3,J7<=TUAN!$C$3+6),MAX(AB$5:AB6)+1,"") -> 2
A8: =IF(C8="","","CV"&TEXT(ROW()-5,"000")) -> CV003 | B8: 46281 | C8: [VÍ DỤ] Sửa nắp hố ga bị vỡ theo phản ánh | D8: =DANH_MUC!A7 -> Đơn vị 3 (sửa tên) | E8: =DANH_MUC!B6 -> Phường 2 (sửa tên) | F8: =DANH_MUC!C7 -> Người 3 (sửa tên) | G8: Phản ánh của dân | H8: Không | I8: Có | J8: 46290 | K8: Chờ duyệt | M8: Dữ liệu minh họa | N8: =IF(C8="","",IF(AND(H8="Có",I8="Có"),"1. Làm ngay",IF(H8="Có","2. Lên lịch",IF(I8="Có","3. Giao lại","4. Để sau")))) -> 3. Giao lại | O8: =IF(OR(C8="",J8="",K8="Hoàn thành"),"",J8-TODAY()) -> 2 | P8: =IF(C8="","",IF(K8="Hoàn thành",IF(OR(L8="",J8=""),"Xong (thiếu ngày)",IF(L8<=J8,"Xong đúng hạn","Xong trễ")),IF(J8="","Chưa có hạn",IF(J8<TODAY(),"Quá hạn",IF(J8=TODAY(),"Đến hạn hôm nay",IF(J8-TODAY()<=3,"Sắp đến hạn","Trong hạn")))))) -> Sắp đến hạn | Q8: =IF(OR(C8="",J8=""),"",WEEKNUM(J8,21)) -> 39 | S8: =IF(AND(C8<>"",K8<>"Hoàn thành",J8<>"",J8<=TODAY()),MAX(S$5:S7)+1,"") | T8: =IF(AND(C8<>"",IF(K8="","Chưa làm",K8)="Chưa làm"),MAX(T$5:T7)+1,"") | U8: =IF(AND(C8<>"",IF(K8="","Chưa làm",K8)="Đang làm"),MAX(U$5:U7)+1,"") | V8: =IF(AND(C8<>"",IF(K8="","Chưa làm",K8)="Chờ duyệt"),MAX(V$5:V7)+1,"") -> 1 | W8: =IF(AND(C8<>"",IF(K8="","Chưa làm",K8)="Hoàn thành"),MAX(W$5:W7)+1,"") | X8: =IF(AND(C8<>"",K8<>"Hoàn thành",N8="1. Làm ngay"),MAX(X$5:X7)+1,"") | Y8: =IF(AND(C8<>"",K8<>"Hoàn thành",N8="2. Lên lịch"),MAX(Y$5:Y7)+1,"") | Z8: =IF(AND(C8<>"",K8<>"Hoàn thành",N8="3. Giao lại"),MAX(Z$5:Z7)+1,"") -> 1 | AA8: =IF(AND(C8<>"",K8<>"Hoàn thành",N8="4. Để sau"),MAX(AA$5:AA7)+1,"") | AB8: =IF(AND(C8<>"",J8<>"",J8>=TUAN!$C$3,J8<=TUAN!$C$3+6),MAX(AB$5:AB7)+1,"") -> 3
A9: =IF(C9="","","CV"&TEXT(ROW()-5,"000")) -> CV004 | B9: 46285 | C9: [VÍ DỤ] Lập kế hoạch trồng cây xanh quý IV | D9: =DANH_MUC!A6 -> Đơn vị 2 (sửa tên) | E9: =DANH_MUC!B7 -> Phường 3 (sửa tên) | F9: =DANH_MUC!C8 -> Người 4 (sửa tên) | G9: Nghị quyết / kế hoạch | H9: Có | I9: Không | J9: 46302 | K9: Chưa làm | M9: Dữ liệu minh họa | N9: =IF(C9="","",IF(AND(H9="Có",I9="Có"),"1. Làm ngay",IF(H9="Có","2. Lên lịch",IF(I9="Có","3. Giao lại","4. Để sau")))) -> 2. Lên lịch | O9: =IF(OR(C9="",J9="",K9="Hoàn thành"),"",J9-TODAY()) -> 14 | P9: =IF(C9="","",IF(K9="Hoàn thành",IF(OR(L9="",J9=""),"Xong (thiếu ngày)",IF(L9<=J9,"Xong đúng hạn","Xong trễ")),IF(J9="","Chưa có hạn",IF(J9<TODAY(),"Quá hạn",IF(J9=TODAY(),"Đến hạn hôm nay",IF(J9-TODAY()<=3,"Sắp đến hạn","Trong hạn")))))) -> Trong hạn | Q9: =IF(OR(C9="",J9=""),"",WEEKNUM(J9,21)) -> 41 | S9: =IF(AND(C9<>"",K9<>"Hoàn thành",J9<>"",J9<=TODAY()),MAX(S$5:S8)+1,"") | T9: =IF(AND(C9<>"",IF(K9="","Chưa làm",K9)="Chưa làm"),MAX(T$5:T8)+1,"") -> 2 | U9: =IF(AND(C9<>"",IF(K9="","Chưa làm",K9)="Đang làm"),MAX(U$5:U8)+1,"") | V9: =IF(AND(C9<>"",IF(K9="","Chưa làm",K9)="Chờ duyệt"),MAX(V$5:V8)+1,"") | W9: =IF(AND(C9<>"",IF(K9="","Chưa làm",K9)="Hoàn thành"),MAX(W$5:W8)+1,"") | X9: =IF(AND(C9<>"",K9<>"Hoàn thành",N9="1. Làm ngay"),MAX(X$5:X8)+1,"") | Y9: =IF(AND(C9<>"",K9<>"Hoàn thành",N9="2. Lên lịch"),MAX(Y$5:Y8)+1,"") -> 1 | Z9: =IF(AND(C9<>"",K9<>"Hoàn thành",N9="3. Giao lại"),MAX(Z$5:Z8)+1,"") | AA9: =IF(AND(C9<>"",K9<>"Hoàn thành",N9="4. Để sau"),MAX(AA$5:AA8)+1,"") | AB9: =IF(AND(C9<>"",J9<>"",J9>=TUAN!$C$3,J9<=TUAN!$C$3+6),MAX(AB$5:AB8)+1,"")
A10: =IF(C10="","","CV"&TEXT(ROW()-5,"000")) -> CV005 | B10: 46276 | C10: [VÍ DỤ] Phun rửa đường sau sự kiện | D10: =DANH_MUC!A5 -> Đơn vị 1 (sửa tên) | E10: =DANH_MUC!B8 -> Phường 4 (sửa tên) | F10: =DANH_MUC!C5 -> Người 1 (sửa tên) | G10: Phát sinh nội bộ | H10: Không | I10: Không | J10: 46284 | K10: Hoàn thành | L10: 46283 | M10: Dữ liệu minh họa | N10: =IF(C10="","",IF(AND(H10="Có",I10="Có"),"1. Làm ngay",IF(H10="Có","2. Lên lịch",IF(I10="Có","3. Giao lại","4. Để sau")))) -> 4. Để sau | O10: =IF(OR(C10="",J10="",K10="Hoàn thành"),"",J10-TODAY()) | P10: =IF(C10="","",IF(K10="Hoàn thành",IF(OR(L10="",J10=""),"Xong (thiếu ngày)",IF(L10<=J10,"Xong đúng hạn","Xong trễ")),IF(J10="","Chưa có hạn",IF(J10<TODAY(),"Quá hạn",IF(J10=TODAY(),"Đến hạn hôm nay",IF(J10-TODAY()<=3,"Sắp đến hạn","Trong hạn")))))) -> Xong đúng hạn | Q10: =IF(OR(C10="",J10=""),"",WEEKNUM(J10,21)) -> 38 | S10: =IF(AND(C10<>"",K10<>"Hoàn thành",J10<>"",J10<=TODAY()),MAX(S$5:S9)+1,"") | T10: =IF(AND(C10<>"",IF(K10="","Chưa làm",K10)="Chưa làm"),MAX(T$5:T9)+1,"") | U10: =IF(AND(C10<>"",IF(K10="","Chưa làm",K10)="Đang làm"),MAX(U$5:U9)+1,"") | V10: =IF(AND(C10<>"",IF(K10="","Chưa làm",K10)="Chờ duyệt"),MAX(V$5:V9)+1,"") | W10: =IF(AND(C10<>"",IF(K10="","Chưa làm",K10)="Hoàn thành"),MAX(W$5:W9)+1,"") -> 1 | X10: =IF(AND(C10<>"",K10<>"Hoàn thành",N10="1. Làm ngay"),MAX(X$5:X9)+1,"") | Y10: =IF(AND(C10<>"",K10<>"Hoàn thành",N10="2. Lên lịch"),MAX(Y$5:Y9)+1,"") | Z10: =IF(AND(C10<>"",K10<>"Hoàn thành",N10="3. Giao lại"),MAX(Z$5:Z9)+1,"") | AA10: =IF(AND(C10<>"",K10<>"Hoàn thành",N10="4. Để sau"),MAX(AA$5:AA9)+1,"") | AB10: =IF(AND(C10<>"",J10<>"",J10>=TUAN!$C$3,J10<=TUAN!$C$3+6),MAX(AB$5:AB9)+1,"")
A11: =IF(C11="","","CV"&TEXT(ROW()-5,"000")) | N11: =IF(C11="","",IF(AND(H11="Có",I11="Có"),"1. Làm ngay",IF(H11="Có","2. Lên lịch",IF(I11="Có","3. Giao lại","4. Để sau")))) | O11: =IF(OR(C11="",J11="",K11="Hoàn thành"),"",J11-TODAY()) | P11: =IF(C11="","",IF(K11="Hoàn thành",IF(OR(L11="",J11=""),"Xong (thiếu ngày)",IF(L11<=J11,"Xong đúng hạn","Xong trễ")),IF(J11="","Chưa có hạn",IF(J11<TODAY(),"Quá hạn",IF(J11=TODAY(),"Đến hạn hôm nay",IF(J11-TODAY()<=3,"Sắp đến hạn","Trong hạn")))))) | Q11: =IF(OR(C11="",J11=""),"",WEEKNUM(J11,21)) | S11: =IF(AND(C11<>"",K11<>"Hoàn thành",J11<>"",J11<=TODAY()),MAX(S$5:S10)+1,"") | T11: =IF(AND(C11<>"",IF(K11="","Chưa làm",K11)="Chưa làm"),MAX(T$5:T10)+1,"") | U11: =IF(AND(C11<>"",IF(K11="","Chưa làm",K11)="Đang làm"),MAX(U$5:U10)+1,"") | V11: =IF(AND(C11<>"",IF(K11="","Chưa làm",K11)="Chờ duyệt"),MAX(V$5:V10)+1,"") | W11: =IF(AND(C11<>"",IF(K11="","Chưa làm",K11)="Hoàn thành"),MAX(W$5:W10)+1,"") | X11: =IF(AND(C11<>"",K11<>"Hoàn thành",N11="1. Làm ngay"),MAX(X$5:X10)+1,"") | Y11: =IF(AND(C11<>"",K11<>"Hoàn thành",N11="2. Lên lịch"),MAX(Y$5:Y10)+1,"") | Z11: =IF(AND(C11<>"",K11<>"Hoàn thành",N11="3. Giao lại"),MAX(Z$5:Z10)+1,"") | AA11: =IF(AND(C11<>"",K11<>"Hoàn thành",N11="4. Để sau"),MAX(AA$5:AA10)+1,"") | AB11: =IF(AND(C11<>"",J11<>"",J11>=TUAN!$C$3,J11<=TUAN!$C$3+6),MAX(AB$5:AB10)+1,"")
A12: =IF(C12="","","CV"&TEXT(ROW()-5,"000")) | N12: =IF(C12="","",IF(AND(H12="Có",I12="Có"),"1. Làm ngay",IF(H12="Có","2. Lên lịch",IF(I12="Có","3. Giao lại","4. Để sau")))) | O12: =IF(OR(C12="",J12="",K12="Hoàn thành"),"",J12-TODAY()) | P12: =IF(C12="","",IF(K12="Hoàn thành",IF(OR(L12="",J12=""),"Xong (thiếu ngày)",IF(L12<=J12,"Xong đúng hạn","Xong trễ")),IF(J12="","Chưa có hạn",IF(J12<TODAY(),"Quá hạn",IF(J12=TODAY(),"Đến hạn hôm nay",IF(J12-TODAY()<=3,"Sắp đến hạn","Trong hạn")))))) | Q12: =IF(OR(C12="",J12=""),"",WEEKNUM(J12,21)) | S12: =IF(AND(C12<>"",K12<>"Hoàn thành",J12<>"",J12<=TODAY()),MAX(S$5:S11)+1,"") | T12: =IF(AND(C12<>"",IF(K12="","Chưa làm",K12)="Chưa làm"),MAX(T$5:T11)+1,"") | U12: =IF(AND(C12<>"",IF(K12="","Chưa làm",K12)="Đang làm"),MAX(U$5:U11)+1,"") | V12: =IF(AND(C12<>"",IF(K12="","Chưa làm",K12)="Chờ duyệt"),MAX(V$5:V11)+1,"") | W12: =IF(AND(C12<>"",IF(K12="","Chưa làm",K12)="Hoàn thành"),MAX(W$5:W11)+1,"") | X12: =IF(AND(C12<>"",K12<>"Hoàn thành",N12="1. Làm ngay"),MAX(X$5:X11)+1,"") | Y12: =IF(AND(C12<>"",K12<>"Hoàn thành",N12="2. Lên lịch"),MAX(Y$5:Y11)+1,"") | Z12: =IF(AND(C12<>"",K12<>"Hoàn thành",N12="3. Giao lại"),MAX(Z$5:Z11)+1,"") | AA12: =IF(AND(C12<>"",K12<>"Hoàn thành",N12="4. Để sau"),MAX(AA$5:AA11)+1,"") | AB12: =IF(AND(C12<>"",J12<>"",J12>=TUAN!$C$3,J12<=TUAN!$C$3+6),MAX(AB$5:AB11)+1,"")
A13: =IF(C13="","","CV"&TEXT(ROW()-5,"000")) | N13: =IF(C13="","",IF(AND(H13="Có",I13="Có"),"1. Làm ngay",IF(H13="Có","2. Lên lịch",IF(I13="Có","3. Giao lại","4. Để sau")))) | O13: =IF(OR(C13="",J13="",K13="Hoàn thành"),"",J13-TODAY()) | P13: =IF(C13="","",IF(K13="Hoàn thành",IF(OR(L13="",J13=""),"Xong (thiếu ngày)",IF(L13<=J13,"Xong đúng hạn","Xong trễ")),IF(J13="","Chưa có hạn",IF(J13<TODAY(),"Quá hạn",IF(J13=TODAY(),"Đến hạn hôm nay",IF(J13-TODAY()<=3,"Sắp đến hạn","Trong hạn")))))) | Q13: =IF(OR(C13="",J13=""),"",WEEKNUM(J13,21)) | S13: =IF(AND(C13<>"",K13<>"Hoàn thành",J13<>"",J13<=TODAY()),MAX(S$5:S12)+1,"") | T13: =IF(AND(C13<>"",IF(K13="","Chưa làm",K13)="Chưa làm"),MAX(T$5:T12)+1,"") | U13: =IF(AND(C13<>"",IF(K13="","Chưa làm",K13)="Đang làm"),MAX(U$5:U12)+1,"") | V13: =IF(AND(C13<>"",IF(K13="","Chưa làm",K13)="Chờ duyệt"),MAX(V$5:V12)+1,"") | W13: =IF(AND(C13<>"",IF(K13="","Chưa làm",K13)="Hoàn thành"),MAX(W$5:W12)+1,"") | X13: =IF(AND(C13<>"",K13<>"Hoàn thành",N13="1. Làm ngay"),MAX(X$5:X12)+1,"") | Y13: =IF(AND(C13<>"",K13<>"Hoàn thành",N13="2. Lên lịch"),MAX(Y$5:Y12)+1,"") | Z13: =IF(AND(C13<>"",K13<>"Hoàn thành",N13="3. Giao lại"),MAX(Z$5:Z12)+1,"") | AA13: =IF(AND(C13<>"",K13<>"Hoàn thành",N13="4. Để sau"),MAX(AA$5:AA12)+1,"") | AB13: =IF(AND(C13<>"",J13<>"",J13>=TUAN!$C$3,J13<=TUAN!$C$3+6),MAX(AB$5:AB12)+1,"")
A14: =IF(C14="","","CV"&TEXT(ROW()-5,"000")) | N14: =IF(C14="","",IF(AND(H14="Có",I14="Có"),"1. Làm ngay",IF(H14="Có","2. Lên lịch",IF(I14="Có","3. Giao lại","4. Để sau")))) | O14: =IF(OR(C14="",J14="",K14="Hoàn thành"),"",J14-TODAY()) | P14: =IF(C14="","",IF(K14="Hoàn thành",IF(OR(L14="",J14=""),"Xong (thiếu ngày)",IF(L14<=J14,"Xong đúng hạn","Xong trễ")),IF(J14="","Chưa có hạn",IF(J14<TODAY(),"Quá hạn",IF(J14=TODAY(),"Đến hạn hôm nay",IF(J14-TODAY()<=3,"Sắp đến hạn","Trong hạn")))))) | Q14: =IF(OR(C14="",J14=""),"",WEEKNUM(J14,21)) | S14: =IF(AND(C14<>"",K14<>"Hoàn thành",J14<>"",J14<=TODAY()),MAX(S$5:S13)+1,"") | T14: =IF(AND(C14<>"",IF(K14="","Chưa làm",K14)="Chưa làm"),MAX(T$5:T13)+1,"") | U14: =IF(AND(C14<>"",IF(K14="","Chưa làm",K14)="Đang làm"),MAX(U$5:U13)+1,"") | V14: =IF(AND(C14<>"",IF(K14="","Chưa làm",K14)="Chờ duyệt"),MAX(V$5:V13)+1,"") | W14: =IF(AND(C14<>"",IF(K14="","Chưa làm",K14)="Hoàn thành"),MAX(W$5:W13)+1,"") | X14: =IF(AND(C14<>"",K14<>"Hoàn thành",N14="1. Làm ngay"),MAX(X$5:X13)+1,"") | Y14: =IF(AND(C14<>"",K14<>"Hoàn thành",N14="2. Lên lịch"),MAX(Y$5:Y13)+1,"") | Z14: =IF(AND(C14<>"",K14<>"Hoàn thành",N14="3. Giao lại"),MAX(Z$5:Z13)+1,"") | AA14: =IF(AND(C14<>"",K14<>"Hoàn thành",N14="4. Để sau"),MAX(AA$5:AA13)+1,"") | AB14: =IF(AND(C14<>"",J14<>"",J14>=TUAN!$C$3,J14<=TUAN!$C$3+6),MAX(AB$5:AB13)+1,"")
A15: =IF(C15="","","CV"&TEXT(ROW()-5,"000")) | N15: =IF(C15="","",IF(AND(H15="Có",I15="Có"),"1. Làm ngay",IF(H15="Có","2. Lên lịch",IF(I15="Có","3. Giao lại","4. Để sau")))) | O15: =IF(OR(C15="",J15="",K15="Hoàn thành"),"",J15-TODAY()) | P15: =IF(C15="","",IF(K15="Hoàn thành",IF(OR(L15="",J15=""),"Xong (thiếu ngày)",IF(L15<=J15,"Xong đúng hạn","Xong trễ")),IF(J15="","Chưa có hạn",IF(J15<TODAY(),"Quá hạn",IF(J15=TODAY(),"Đến hạn hôm nay",IF(J15-TODAY()<=3,"Sắp đến hạn","Trong hạn")))))) | Q15: =IF(OR(C15="",J15=""),"",WEEKNUM(J15,21)) | S15: =IF(AND(C15<>"",K15<>"Hoàn thành",J15<>"",J15<=TODAY()),MAX(S$5:S14)+1,"") | T15: =IF(AND(C15<>"",IF(K15="","Chưa làm",K15)="Chưa làm"),MAX(T$5:T14)+1,"") | U15: =IF(AND(C15<>"",IF(K15="","Chưa làm",K15)="Đang làm"),MAX(U$5:U14)+1,"") | V15: =IF(AND(C15<>"",IF(K15="","Chưa làm",K15)="Chờ duyệt"),MAX(V$5:V14)+1,"") | W15: =IF(AND(C15<>"",IF(K15="","Chưa làm",K15)="Hoàn thành"),MAX(W$5:W14)+1,"") | X15: =IF(AND(C15<>"",K15<>"Hoàn thành",N15="1. Làm ngay"),MAX(X$5:X14)+1,"") | Y15: =IF(AND(C15<>"",K15<>"Hoàn thành",N15="2. Lên lịch"),MAX(Y$5:Y14)+1,"") | Z15: =IF(AND(C15<>"",K15<>"Hoàn thành",N15="3. Giao lại"),MAX(Z$5:Z14)+1,"") | AA15: =IF(AND(C15<>"",K15<>"Hoàn thành",N15="4. Để sau"),MAX(AA$5:AA14)+1,"") | AB15: =IF(AND(C15<>"",J15<>"",J15>=TUAN!$C$3,J15<=TUAN!$C$3+6),MAX(AB$5:AB14)+1,"")
A16: =IF(C16="","","CV"&TEXT(ROW()-5,"000")) | N16: =IF(C16="","",IF(AND(H16="Có",I16="Có"),"1. Làm ngay",IF(H16="Có","2. Lên lịch",IF(I16="Có","3. Giao lại","4. Để sau")))) | O16: =IF(OR(C16="",J16="",K16="Hoàn thành"),"",J16-TODAY()) | P16: =IF(C16="","",IF(K16="Hoàn thành",IF(OR(L16="",J16=""),"Xong (thiếu ngày)",IF(L16<=J16,"Xong đúng hạn","Xong trễ")),IF(J16="","Chưa có hạn",IF(J16<TODAY(),"Quá hạn",IF(J16=TODAY(),"Đến hạn hôm nay",IF(J16-TODAY()<=3,"Sắp đến hạn","Trong hạn")))))) | Q16: =IF(OR(C16="",J16=""),"",WEEKNUM(J16,21)) | S16: =IF(AND(C16<>"",K16<>"Hoàn thành",J16<>"",J16<=TODAY()),MAX(S$5:S15)+1,"") | T16: =IF(AND(C16<>"",IF(K16="","Chưa làm",K16)="Chưa làm"),MAX(T$5:T15)+1,"") | U16: =IF(AND(C16<>"",IF(K16="","Chưa làm",K16)="Đang làm"),MAX(U$5:U15)+1,"") | V16: =IF(AND(C16<>"",IF(K16="","Chưa làm",K16)="Chờ duyệt"),MAX(V$5:V15)+1,"") | W16: =IF(AND(C16<>"",IF(K16="","Chưa làm",K16)="Hoàn thành"),MAX(W$5:W15)+1,"") | X16: =IF(AND(C16<>"",K16<>"Hoàn thành",N16="1. Làm ngay"),MAX(X$5:X15)+1,"") | Y16: =IF(AND(C16<>"",K16<>"Hoàn thành",N16="2. Lên lịch"),MAX(Y$5:Y15)+1,"") | Z16: =IF(AND(C16<>"",K16<>"Hoàn thành",N16="3. Giao lại"),MAX(Z$5:Z15)+1,"") | AA16: =IF(AND(C16<>"",K16<>"Hoàn thành",N16="4. Để sau"),MAX(AA$5:AA15)+1,"") | AB16: =IF(AND(C16<>"",J16<>"",J16>=TUAN!$C$3,J16<=TUAN!$C$3+6),MAX(AB$5:AB15)+1,"")
A17: =IF(C17="","","CV"&TEXT(ROW()-5,"000")) | N17: =IF(C17="","",IF(AND(H17="Có",I17="Có"),"1. Làm ngay",IF(H17="Có","2. Lên lịch",IF(I17="Có","3. Giao lại","4. Để sau")))) | O17: =IF(OR(C17="",J17="",K17="Hoàn thành"),"",J17-TODAY()) | P17: =IF(C17="","",IF(K17="Hoàn thành",IF(OR(L17="",J17=""),"Xong (thiếu ngày)",IF(L17<=J17,"Xong đúng hạn","Xong trễ")),IF(J17="","Chưa có hạn",IF(J17<TODAY(),"Quá hạn",IF(J17=TODAY(),"Đến hạn hôm nay",IF(J17-TODAY()<=3,"Sắp đến hạn","Trong hạn")))))) | Q17: =IF(OR(C17="",J17=""),"",WEEKNUM(J17,21)) | S17: =IF(AND(C17<>"",K17<>"Hoàn thành",J17<>"",J17<=TODAY()),MAX(S$5:S16)+1,"") | T17: =IF(AND(C17<>"",IF(K17="","Chưa làm",K17)="Chưa làm"),MAX(T$5:T16)+1,"") | U17: =IF(AND(C17<>"",IF(K17="","Chưa làm",K17)="Đang làm"),MAX(U$5:U16)+1,"") | V17: =IF(AND(C17<>"",IF(K17="","Chưa làm",K17)="Chờ duyệt"),MAX(V$5:V16)+1,"") | W17: =IF(AND(C17<>"",IF(K17="","Chưa làm",K17)="Hoàn thành"),MAX(W$5:W16)+1,"") | X17: =IF(AND(C17<>"",K17<>"Hoàn thành",N17="1. Làm ngay"),MAX(X$5:X16)+1,"") | Y17: =IF(AND(C17<>"",K17<>"Hoàn thành",N17="2. Lên lịch"),MAX(Y$5:Y16)+1,"") | Z17: =IF(AND(C17<>"",K17<>"Hoàn thành",N17="3. Giao lại"),MAX(Z$5:Z16)+1,"") | AA17: =IF(AND(C17<>"",K17<>"Hoàn thành",N17="4. Để sau"),MAX(AA$5:AA16)+1,"") | AB17: =IF(AND(C17<>"",J17<>"",J17>=TUAN!$C$3,J17<=TUAN!$C$3+6),MAX(AB$5:AB16)+1,"")
A18: =IF(C18="","","CV"&TEXT(ROW()-5,"000")) | N18: =IF(C18="","",IF(AND(H18="Có",I18="Có"),"1. Làm ngay",IF(H18="Có","2. Lên lịch",IF(I18="Có","3. Giao lại","4. Để sau")))) | O18: =IF(OR(C18="",J18="",K18="Hoàn thành"),"",J18-TODAY()) | P18: =IF(C18="","",IF(K18="Hoàn thành",IF(OR(L18="",J18=""),"Xong (thiếu ngày)",IF(L18<=J18,"Xong đúng hạn","Xong trễ")),IF(J18="","Chưa có hạn",IF(J18<TODAY(),"Quá hạn",IF(J18=TODAY(),"Đến hạn hôm nay",IF(J18-TODAY()<=3,"Sắp đến hạn","Trong hạn")))))) | Q18: =IF(OR(C18="",J18=""),"",WEEKNUM(J18,21)) | S18: =IF(AND(C18<>"",K18<>"Hoàn thành",J18<>"",J18<=TODAY()),MAX(S$5:S17)+1,"") | T18: =IF(AND(C18<>"",IF(K18="","Chưa làm",K18)="Chưa làm"),MAX(T$5:T17)+1,"") | U18: =IF(AND(C18<>"",IF(K18="","Chưa làm",K18)="Đang làm"),MAX(U$5:U17)+1,"") | V18: =IF(AND(C18<>"",IF(K18="","Chưa làm",K18)="Chờ duyệt"),MAX(V$5:V17)+1,"") | W18: =IF(AND(C18<>"",IF(K18="","Chưa làm",K18)="Hoàn thành"),MAX(W$5:W17)+1,"") | X18: =IF(AND(C18<>"",K18<>"Hoàn thành",N18="1. Làm ngay"),MAX(X$5:X17)+1,"") | Y18: =IF(AND(C18<>"",K18<>"Hoàn thành",N18="2. Lên lịch"),MAX(Y$5:Y17)+1,"") | Z18: =IF(AND(C18<>"",K18<>"Hoàn thành",N18="3. Giao lại"),MAX(Z$5:Z17)+1,"") | AA18: =IF(AND(C18<>"",K18<>"Hoàn thành",N18="4. Để sau"),MAX(AA$5:AA17)+1,"") | AB18: =IF(AND(C18<>"",J18<>"",J18>=TUAN!$C$3,J18<=TUAN!$C$3+6),MAX(AB$5:AB17)+1,"")
A19: =IF(C19="","","CV"&TEXT(ROW()-5,"000")) | N19: =IF(C19="","",IF(AND(H19="Có",I19="Có"),"1. Làm ngay",IF(H19="Có","2. Lên lịch",IF(I19="Có","3. Giao lại","4. Để sau")))) | O19: =IF(OR(C19="",J19="",K19="Hoàn thành"),"",J19-TODAY()) | P19: =IF(C19="","",IF(K19="Hoàn thành",IF(OR(L19="",J19=""),"Xong (thiếu ngày)",IF(L19<=J19,"Xong đúng hạn","Xong trễ")),IF(J19="","Chưa có hạn",IF(J19<TODAY(),"Quá hạn",IF(J19=TODAY(),"Đến hạn hôm nay",IF(J19-TODAY()<=3,"Sắp đến hạn","Trong hạn")))))) | Q19: =IF(OR(C19="",J19=""),"",WEEKNUM(J19,21)) | S19: =IF(AND(C19<>"",K19<>"Hoàn thành",J19<>"",J19<=TODAY()),MAX(S$5:S18)+1,"") | T19: =IF(AND(C19<>"",IF(K19="","Chưa làm",K19)="Chưa làm"),MAX(T$5:T18)+1,"") | U19: =IF(AND(C19<>"",IF(K19="","Chưa làm",K19)="Đang làm"),MAX(U$5:U18)+1,"") | V19: =IF(AND(C19<>"",IF(K19="","Chưa làm",K19)="Chờ duyệt"),MAX(V$5:V18)+1,"") | W19: =IF(AND(C19<>"",IF(K19="","Chưa làm",K19)="Hoàn thành"),MAX(W$5:W18)+1,"") | X19: =IF(AND(C19<>"",K19<>"Hoàn thành",N19="1. Làm ngay"),MAX(X$5:X18)+1,"") | Y19: =IF(AND(C19<>"",K19<>"Hoàn thành",N19="2. Lên lịch"),MAX(Y$5:Y18)+1,"") | Z19: =IF(AND(C19<>"",K19<>"Hoàn thành",N19="3. Giao lại"),MAX(Z$5:Z18)+1,"") | AA19: =IF(AND(C19<>"",K19<>"Hoàn thành",N19="4. Để sau"),MAX(AA$5:AA18)+1,"") | AB19: =IF(AND(C19<>"",J19<>"",J19>=TUAN!$C$3,J19<=TUAN!$C$3+6),MAX(AB$5:AB18)+1,"")
A20: =IF(C20="","","CV"&TEXT(ROW()-5,"000")) | N20: =IF(C20="","",IF(AND(H20="Có",I20="Có"),"1. Làm ngay",IF(H20="Có","2. Lên lịch",IF(I20="Có","3. Giao lại","4. Để sau")))) | O20: =IF(OR(C20="",J20="",K20="Hoàn thành"),"",J20-TODAY()) | P20: =IF(C20="","",IF(K20="Hoàn thành",IF(OR(L20="",J20=""),"Xong (thiếu ngày)",IF(L20<=J20,"Xong đúng hạn","Xong trễ")),IF(J20="","Chưa có hạn",IF(J20<TODAY(),"Quá hạn",IF(J20=TODAY(),"Đến hạn hôm nay",IF(J20-TODAY()<=3,"Sắp đến hạn","Trong hạn")))))) | Q20: =IF(OR(C20="",J20=""),"",WEEKNUM(J20,21)) | S20: =IF(AND(C20<>"",K20<>"Hoàn thành",J20<>"",J20<=TODAY()),MAX(S$5:S19)+1,"") | T20: =IF(AND(C20<>"",IF(K20="","Chưa làm",K20)="Chưa làm"),MAX(T$5:T19)+1,"") | U20: =IF(AND(C20<>"",IF(K20="","Chưa làm",K20)="Đang làm"),MAX(U$5:U19)+1,"") | V20: =IF(AND(C20<>"",IF(K20="","Chưa làm",K20)="Chờ duyệt"),MAX(V$5:V19)+1,"") | W20: =IF(AND(C20<>"",IF(K20="","Chưa làm",K20)="Hoàn thành"),MAX(W$5:W19)+1,"") | X20: =IF(AND(C20<>"",K20<>"Hoàn thành",N20="1. Làm ngay"),MAX(X$5:X19)+1,"") | Y20: =IF(AND(C20<>"",K20<>"Hoàn thành",N20="2. Lên lịch"),MAX(Y$5:Y19)+1,"") | Z20: =IF(AND(C20<>"",K20<>"Hoàn thành",N20="3. Giao lại"),MAX(Z$5:Z19)+1,"") | AA20: =IF(AND(C20<>"",K20<>"Hoàn thành",N20="4. Để sau"),MAX(AA$5:AA19)+1,"") | AB20: =IF(AND(C20<>"",J20<>"",J20>=TUAN!$C$3,J20<=TUAN!$C$3+6),MAX(AB$5:AB19)+1,"")
A21: =IF(C21="","","CV"&TEXT(ROW()-5,"000")) | N21: =IF(C21="","",IF(AND(H21="Có",I21="Có"),"1. Làm ngay",IF(H21="Có","2. Lên lịch",IF(I21="Có","3. Giao lại","4. Để sau")))) | O21: =IF(OR(C21="",J21="",K21="Hoàn thành"),"",J21-TODAY()) | P21: =IF(C21="","",IF(K21="Hoàn thành",IF(OR(L21="",J21=""),"Xong (thiếu ngày)",IF(L21<=J21,"Xong đúng hạn","Xong trễ")),IF(J21="","Chưa có hạn",IF(J21<TODAY(),"Quá hạn",IF(J21=TODAY(),"Đến hạn hôm nay",IF(J21-TODAY()<=3,"Sắp đến hạn","Trong hạn")))))) | Q21: =IF(OR(C21="",J21=""),"",WEEKNUM(J21,21)) | S21: =IF(AND(C21<>"",K21<>"Hoàn thành",J21<>"",J21<=TODAY()),MAX(S$5:S20)+1,"") | T21: =IF(AND(C21<>"",IF(K21="","Chưa làm",K21)="Chưa làm"),MAX(T$5:T20)+1,"") | U21: =IF(AND(C21<>"",IF(K21="","Chưa làm",K21)="Đang làm"),MAX(U$5:U20)+1,"") | V21: =IF(AND(C21<>"",IF(K21="","Chưa làm",K21)="Chờ duyệt"),MAX(V$5:V20)+1,"") | W21: =IF(AND(C21<>"",IF(K21="","Chưa làm",K21)="Hoàn thành"),MAX(W$5:W20)+1,"") | X21: =IF(AND(C21<>"",K21<>"Hoàn thành",N21="1. Làm ngay"),MAX(X$5:X20)+1,"") | Y21: =IF(AND(C21<>"",K21<>"Hoàn thành",N21="2. Lên lịch"),MAX(Y$5:Y20)+1,"") | Z21: =IF(AND(C21<>"",K21<>"Hoàn thành",N21="3. Giao lại"),MAX(Z$5:Z20)+1,"") | AA21: =IF(AND(C21<>"",K21<>"Hoàn thành",N21="4. Để sau"),MAX(AA$5:AA20)+1,"") | AB21: =IF(AND(C21<>"",J21<>"",J21>=TUAN!$C$3,J21<=TUAN!$C$3+6),MAX(AB$5:AB20)+1,"")
A22: =IF(C22="","","CV"&TEXT(ROW()-5,"000")) | N22: =IF(C22="","",IF(AND(H22="Có",I22="Có"),"1. Làm ngay",IF(H22="Có","2. Lên lịch",IF(I22="Có","3. Giao lại","4. Để sau")))) | O22: =IF(OR(C22="",J22="",K22="Hoàn thành"),"",J22-TODAY()) | P22: =IF(C22="","",IF(K22="Hoàn thành",IF(OR(L22="",J22=""),"Xong (thiếu ngày)",IF(L22<=J22,"Xong đúng hạn","Xong trễ")),IF(J22="","Chưa có hạn",IF(J22<TODAY(),"Quá hạn",IF(J22=TODAY(),"Đến hạn hôm nay",IF(J22-TODAY()<=3,"Sắp đến hạn","Trong hạn")))))) | Q22: =IF(OR(C22="",J22=""),"",WEEKNUM(J22,21)) | S22: =IF(AND(C22<>"",K22<>"Hoàn thành",J22<>"",J22<=TODAY()),MAX(S$5:S21)+1,"") | T22: =IF(AND(C22<>"",IF(K22="","Chưa làm",K22)="Chưa làm"),MAX(T$5:T21)+1,"") | U22: =IF(AND(C22<>"",IF(K22="","Chưa làm",K22)="Đang làm"),MAX(U$5:U21)+1,"") | V22: =IF(AND(C22<>"",IF(K22="","Chưa làm",K22)="Chờ duyệt"),MAX(V$5:V21)+1,"") | W22: =IF(AND(C22<>"",IF(K22="","Chưa làm",K22)="Hoàn thành"),MAX(W$5:W21)+1,"") | X22: =IF(AND(C22<>"",K22<>"Hoàn thành",N22="1. Làm ngay"),MAX(X$5:X21)+1,"") | Y22: =IF(AND(C22<>"",K22<>"Hoàn thành",N22="2. Lên lịch"),MAX(Y$5:Y21)+1,"") | Z22: =IF(AND(C22<>"",K22<>"Hoàn thành",N22="3. Giao lại"),MAX(Z$5:Z21)+1,"") | AA22: =IF(AND(C22<>"",K22<>"Hoàn thành",N22="4. Để sau"),MAX(AA$5:AA21)+1,"") | AB22: =IF(AND(C22<>"",J22<>"",J22>=TUAN!$C$3,J22<=TUAN!$C$3+6),MAX(AB$5:AB21)+1,"")
... A305: =IF(C305="","","CV"&TEXT(ROW()-5,"000")) | N305: =IF(C305="","",IF(AND(H305="Có",I305="Có"),"1. Làm ngay",IF(H305="Có","2. Lên lịch",IF(I305="Có","3. Giao lại","4. Để sau")))) | O305: =IF(OR(C305="",J305="",K305="Hoàn thành"),"",J305-TODAY()) | P305: =IF(C305="","",IF(K305="Hoàn thành",IF(OR(L305="",J305=""),"Xong (thiếu ngày)",IF(L305<=J305,"Xong đúng hạn","Xong trễ")),IF(J305="","Chưa có hạn",IF(J305<TODAY(),"Quá hạn",IF(J305=TODAY(),"Đến hạn hôm nay",IF(J305-TODAY()<=3,"Sắp đến hạn","Trong hạn")))))) | Q305: =IF(OR(C305="",J305=""),"",WEEKNUM(J305,21)) | S305: =IF(AND(C305<>"",K305<>"Hoàn thành",J305<>"",J305<=TODAY()),MAX(S$5:S304)+1,"") | T305: =IF(AND(C305<>"",IF(K305="","Chưa làm",K305)="Chưa làm"),MAX(T$5:T304)+1,"") | U305: =IF(AND(C305<>"",IF(K305="","Chưa làm",K305)="Đang làm"),MAX(U$5:U304)+1,"") | V305: =IF(AND(C305<>"",IF(K305="","Chưa làm",K305)="Chờ duyệt"),MAX(V$5:V304)+1,"") | W305: =IF(AND(C305<>"",IF(K305="","Chưa làm",K305)="Hoàn thành"),MAX(W$5:W304)+1,"") | X305: =IF(AND(C305<>"",K305<>"Hoàn thành",N305="1. Làm ngay"),MAX(X$5:X304)+1,"") | Y305: =IF(AND(C305<>"",K305<>"Hoàn thành",N305="2. Lên lịch"),MAX(Y$5:Y304)+1,"") | Z305: =IF(AND(C305<>"",K305<>"Hoàn thành",N305="3. Giao lại"),MAX(Z$5:Z304)+1,"") | AA305: =IF(AND(C305<>"",K305<>"Hoàn thành",N305="4. Để sau"),MAX(AA$5:AA304)+1,"") | AB305: =IF(AND(C305<>"",J305<>"",J305>=TUAN!$C$3,J305<=TUAN!$C$3+6),MAX(AB$5:AB304)+1,"")

Sheet DASHBOARD
A1: DASHBOARD & KPI
A2: Số liệu tự tính từ sheet CONG_VIEC. Tỷ lệ đúng hạn = Xong đúng hạn / (Xong đúng hạn + Xong trễ).
A3: Cập nhật đến: | B3: =TODAY() -> 46288
A5: Tổng số việc | C5: Đang mở | E5: Quá hạn | G5: Đến hạn trong 3 ngày | I5: Đã hoàn thành | K5: Tỷ lệ xong đúng hạn | M5: KPI 1: có hạn + có người
A6: =COUNTIF(CONG_VIEC!$C$6:$C$305,"?*") -> 5 | C6: =COUNTIF(CONG_VIEC!$C$6:$C$305,"?*")-COUNTIF(CONG_VIEC!$K$6:$K$305,"Hoàn thành") -> 4 | E6: =COUNTIF(CONG_VIEC!$P$6:$P$305,"Quá hạn") -> 1 | G6: =COUNTIF(CONG_VIEC!$P$6:$P$305,"Sắp đến hạn")+COUNTIF(CONG_VIEC!$P$6:$P$305,"Đến hạn hôm nay") -> 2 | I6: =COUNTIF(CONG_VIEC!$K$6:$K$305,"Hoàn thành") -> 1 | K6: =IFERROR(COUNTIF(CONG_VIEC!$P$6:$P$305,"Xong đúng hạn")/(COUNTIF(CONG_VIEC!$P$6:$P$305,"Xong đúng hạn")+COUNTIF(CONG_VIEC!$P$6:$P$305,"Xong trễ")),"") -> 1 | M6: =IFERROR(COUNTIFS(CONG_VIEC!$C$6:$C$305,"?*",CONG_VIEC!$J$6:$J$305,"<>",CONG_VIEC!$F$6:$F$305,"?*")/COUNTIF(CONG_VIEC!$C$6:$C$305,"?*"),"") -> 1
M7: Mục tiêu KPI 1: 100%
A9: THỐNG KÊ THEO ĐƠN VỊ
A10: Đơn vị | B10: Tổng việc | C10: Đang mở | D10: Quá hạn | E10: Sắp đến hạn | F10: Hoàn thành | G10: Xong đúng hạn | H10: Xong trễ | I10: Tỷ lệ đúng hạn | J10: Tỷ lệ hoàn thành
A11: =IF(DANH_MUC!A5="","",DANH_MUC!A5) -> Đơn vị 1 (sửa tên) | B11: =IF(A11="","",COUNTIF(CONG_VIEC!$D$6:$D$305,A11)) -> 2 | C11: =IF(A11="","",B11-COUNTIFS(CONG_VIEC!$D$6:$D$305,A11,CONG_VIEC!$K$6:$K$305,"Hoàn thành")) -> 1 | D11: =IF(A11="","",COUNTIFS(CONG_VIEC!$D$6:$D$305,A11,CONG_VIEC!$P$6:$P$305,"Quá hạn")) -> 1 | E11: =IF(A11="","",COUNTIFS(CONG_VIEC!$D$6:$D$305,A11,CONG_VIEC!$P$6:$P$305,"Sắp đến hạn")+COUNTIFS(CONG_VIEC!$D$6:$D$305,A11,CONG_VIEC!$P$6:$P$305,"Đến hạn hôm nay")) -> 0 | F11: =IF(A11="","",COUNTIFS(CONG_VIEC!$D$6:$D$305,A11,CONG_VIEC!$K$6:$K$305,"Hoàn thành")) -> 1 | G11: =IF(A11="","",COUNTIFS(CONG_VIEC!$D$6:$D$305,A11,CONG_VIEC!$P$6:$P$305,"Xong đúng hạn")) -> 1 | H11: =IF(A11="","",COUNTIFS(CONG_VIEC!$D$6:$D$305,A11,CONG_VIEC!$P$6:$P$305,"Xong trễ")) -> 0 | I11: =IF(A11="","",IFERROR(G11/(G11+H11),"-")) -> 1 | J11: =IF(A11="","",IFERROR(F11/B11,"-")) -> 0.5
A12: =IF(DANH_MUC!A6="","",DANH_MUC!A6) -> Đơn vị 2 (sửa tên) | B12: =IF(A12="","",COUNTIF(CONG_VIEC!$D$6:$D$305,A12)) -> 2 | C12: =IF(A12="","",B12-COUNTIFS(CONG_VIEC!$D$6:$D$305,A12,CONG_VIEC!$K$6:$K$305,"Hoàn thành")) -> 2 | D12: =IF(A12="","",COUNTIFS(CONG_VIEC!$D$6:$D$305,A12,CONG_VIEC!$P$6:$P$305,"Quá hạn")) -> 0 | E12: =IF(A12="","",COUNTIFS(CONG_VIEC!$D$6:$D$305,A12,CONG_VIEC!$P$6:$P$305,"Sắp đến hạn")+COUNTIFS(CONG_VIEC!$D$6:$D$305,A12,CONG_VIEC!$P$6:$P$305,"Đến hạn hôm nay")) -> 1 | F12: =IF(A12="","",COUNTIFS(CONG_VIEC!$D$6:$D$305,A12,CONG_VIEC!$K$6:$K$305,"Hoàn thành")) -> 0 | G12: =IF(A12="","",COUNTIFS(CONG_VIEC!$D$6:$D$305,A12,CONG_VIEC!$P$6:$P$305,"Xong đúng hạn")) -> 0 | H12: =IF(A12="","",COUNTIFS(CONG_VIEC!$D$6:$D$305,A12,CONG_VIEC!$P$6:$P$305,"Xong trễ")) -> 0 | I12: =IF(A12="","",IFERROR(G12/(G12+H12),"-")) -> - | J12: =IF(A12="","",IFERROR(F12/B12,"-")) -> 0
A13: =IF(DANH_MUC!A7="","",DANH_MUC!A7) -> Đơn vị 3 (sửa tên) | B13: =IF(A13="","",COUNTIF(CONG_VIEC!$D$6:$D$305,A13)) -> 1 | C13: =IF(A13="","",B13-COUNTIFS(CONG_VIEC!$D$6:$D$305,A13,CONG_VIEC!$K$6:$K$305,"Hoàn thành")) -> 1 | D13: =IF(A13="","",COUNTIFS(CONG_VIEC!$D$6:$D$305,A13,CONG_VIEC!$P$6:$P$305,"Quá hạn")) -> 0 | E13: =IF(A13="","",COUNTIFS(CONG_VIEC!$D$6:$D$305,A13,CONG_VIEC!$P$6:$P$305,"Sắp đến hạn")+COUNTIFS(CONG_VIEC!$D$6:$D$305,A13,CONG_VIEC!$P$6:$P$305,"Đến hạn hôm nay")) -> 1 | F13: =IF(A13="","",COUNTIFS(CONG_VIEC!$D$6:$D$305,A13,CONG_VIEC!$K$6:$K$305,"Hoàn thành")) -> 0 | G13: =IF(A13="","",COUNTIFS(CONG_VIEC!$D$6:$D$305,A13,CONG_VIEC!$P$6:$P$305,"Xong đúng hạn")) -> 0 | H13: =IF(A13="","",COUNTIFS(CONG_VIEC!$D$6:$D$305,A13,CONG_VIEC!$P$6:$P$305,"Xong trễ")) -> 0 | I13: =IF(A13="","",IFERROR(G13/(G13+H13),"-")) -> - | J13: =IF(A13="","",IFERROR(F13/B13,"-")) -> 0
A14: =IF(DANH_MUC!A8="","",DANH_MUC!A8) -> Đơn vị 4 (sửa tên) | B14: =IF(A14="","",COUNTIF(CONG_VIEC!$D$6:$D$305,A14)) -> 0 | C14: =IF(A14="","",B14-COUNTIFS(CONG_VIEC!$D$6:$D$305,A14,CONG_VIEC!$K$6:$K$305,"Hoàn thành")) -> 0 | D14: =IF(A14="","",COUNTIFS(CONG_VIEC!$D$6:$D$305,A14,CONG_VIEC!$P$6:$P$305,"Quá hạn")) -> 0 | E14: =IF(A14="","",COUNTIFS(CONG_VIEC!$D$6:$D$305,A14,CONG_VIEC!$P$6:$P$305,"Sắp đến hạn")+COUNTIFS(CONG_VIEC!$D$6:$D$305,A14,CONG_VIEC!$P$6:$P$305,"Đến hạn hôm nay")) -> 0 | F14: =IF(A14="","",COUNTIFS(CONG_VIEC!$D$6:$D$305,A14,CONG_VIEC!$K$6:$K$305,"Hoàn thành")) -> 0 | G14: =IF(A14="","",COUNTIFS(CONG_VIEC!$D$6:$D$305,A14,CONG_VIEC!$P$6:$P$305,"Xong đúng hạn")) -> 0 | H14: =IF(A14="","",COUNTIFS(CONG_VIEC!$D$6:$D$305,A14,CONG_VIEC!$P$6:$P$305,"Xong trễ")) -> 0 | I14: =IF(A14="","",IFERROR(G14/(G14+H14),"-")) -> - | J14: =IF(A14="","",IFERROR(F14/B14,"-")) -> -
A15: =IF(DANH_MUC!A9="","",DANH_MUC!A9) -> Đơn vị 5 (sửa tên) | B15: =IF(A15="","",COUNTIF(CONG_VIEC!$D$6:$D$305,A15)) -> 0 | C15: =IF(A15="","",B15-COUNTIFS(CONG_VIEC!$D$6:$D$305,A15,CONG_VIEC!$K$6:$K$305,"Hoàn thành")) -> 0 | D15: =IF(A15="","",COUNTIFS(CONG_VIEC!$D$6:$D$305,A15,CONG_VIEC!$P$6:$P$305,"Quá hạn")) -> 0 | E15: =IF(A15="","",COUNTIFS(CONG_VIEC!$D$6:$D$305,A15,CONG_VIEC!$P$6:$P$305,"Sắp đến hạn")+COUNTIFS(CONG_VIEC!$D$6:$D$305,A15,CONG_VIEC!$P$6:$P$305,"Đến hạn hôm nay")) -> 0 | F15: =IF(A15="","",COUNTIFS(CONG_VIEC!$D$6:$D$305,A15,CONG_VIEC!$K$6:$K$305,"Hoàn thành")) -> 0 | G15: =IF(A15="","",COUNTIFS(CONG_VIEC!$D$6:$D$305,A15,CONG_VIEC!$P$6:$P$305,"Xong đúng hạn")) -> 0 | H15: =IF(A15="","",COUNTIFS(CONG_VIEC!$D$6:$D$305,A15,CONG_VIEC!$P$6:$P$305,"Xong trễ")) -> 0 | I15: =IF(A15="","",IFERROR(G15/(G15+H15),"-")) -> - | J15: =IF(A15="","",IFERROR(F15/B15,"-")) -> -
A16: =IF(DANH_MUC!A10="","",DANH_MUC!A10) -> Đơn vị 6 (sửa tên) | B16: =IF(A16="","",COUNTIF(CONG_VIEC!$D$6:$D$305,A16)) -> 0 | C16: =IF(A16="","",B16-COUNTIFS(CONG_VIEC!$D$6:$D$305,A16,CONG_VIEC!$K$6:$K$305,"Hoàn thành")) -> 0 | D16: =IF(A16="","",COUNTIFS(CONG_VIEC!$D$6:$D$305,A16,CONG_VIEC!$P$6:$P$305,"Quá hạn")) -> 0 | E16: =IF(A16="","",COUNTIFS(CONG_VIEC!$D$6:$D$305,A16,CONG_VIEC!$P$6:$P$305,"Sắp đến hạn")+COUNTIFS(CONG_VIEC!$D$6:$D$305,A16,CONG_VIEC!$P$6:$P$305,"Đến hạn hôm nay")) -> 0 | F16: =IF(A16="","",COUNTIFS(CONG_VIEC!$D$6:$D$305,A16,CONG_VIEC!$K$6:$K$305,"Hoàn thành")) -> 0 | G16: =IF(A16="","",COUNTIFS(CONG_VIEC!$D$6:$D$305,A16,CONG_VIEC!$P$6:$P$305,"Xong đúng hạn")) -> 0 | H16: =IF(A16="","",COUNTIFS(CONG_VIEC!$D$6:$D$305,A16,CONG_VIEC!$P$6:$P$305,"Xong trễ")) -> 0 | I16: =IF(A16="","",IFERROR(G16/(G16+H16),"-")) -> - | J16: =IF(A16="","",IFERROR(F16/B16,"-")) -> -
A17: =IF(DANH_MUC!A11="","",DANH_MUC!A11) | B17: =IF(A17="","",COUNTIF(CONG_VIEC!$D$6:$D$305,A17)) | C17: =IF(A17="","",B17-COUNTIFS(CONG_VIEC!$D$6:$D$305,A17,CONG_VIEC!$K$6:$K$305,"Hoàn thành")) | D17: =IF(A17="","",COUNTIFS(CONG_VIEC!$D$6:$D$305,A17,CONG_VIEC!$P$6:$P$305,"Quá hạn")) | E17: =IF(A17="","",COUNTIFS(CONG_VIEC!$D$6:$D$305,A17,CONG_VIEC!$P$6:$P$305,"Sắp đến hạn")+COUNTIFS(CONG_VIEC!$D$6:$D$305,A17,CONG_VIEC!$P$6:$P$305,"Đến hạn hôm nay")) | F17: =IF(A17="","",COUNTIFS(CONG_VIEC!$D$6:$D$305,A17,CONG_VIEC!$K$6:$K$305,"Hoàn thành")) | G17: =IF(A17="","",COUNTIFS(CONG_VIEC!$D$6:$D$305,A17,CONG_VIEC!$P$6:$P$305,"Xong đúng hạn")) | H17: =IF(A17="","",COUNTIFS(CONG_VIEC!$D$6:$D$305,A17,CONG_VIEC!$P$6:$P$305,"Xong trễ")) | I17: =IF(A17="","",IFERROR(G17/(G17+H17),"-")) | J17: =IF(A17="","",IFERROR(F17/B17,"-"))
A18: =IF(DANH_MUC!A12="","",DANH_MUC!A12) | B18: =IF(A18="","",COUNTIF(CONG_VIEC!$D$6:$D$305,A18)) | C18: =IF(A18="","",B18-COUNTIFS(CONG_VIEC!$D$6:$D$305,A18,CONG_VIEC!$K$6:$K$305,"Hoàn thành")) | D18: =IF(A18="","",COUNTIFS(CONG_VIEC!$D$6:$D$305,A18,CONG_VIEC!$P$6:$P$305,"Quá hạn")) | E18: =IF(A18="","",COUNTIFS(CONG_VIEC!$D$6:$D$305,A18,CONG_VIEC!$P$6:$P$305,"Sắp đến hạn")+COUNTIFS(CONG_VIEC!$D$6:$D$305,A18,CONG_VIEC!$P$6:$P$305,"Đến hạn hôm nay")) | F18: =IF(A18="","",COUNTIFS(CONG_VIEC!$D$6:$D$305,A18,CONG_VIEC!$K$6:$K$305,"Hoàn thành")) | G18: =IF(A18="","",COUNTIFS(CONG_VIEC!$D$6:$D$305,A18,CONG_VIEC!$P$6:$P$305,"Xong đúng hạn")) | H18: =IF(A18="","",COUNTIFS(CONG_VIEC!$D$6:$D$305,A18,CONG_VIEC!$P$6:$P$305,"Xong trễ")) | I18: =IF(A18="","",IFERROR(G18/(G18+H18),"-")) | J18: =IF(A18="","",IFERROR(F18/B18,"-"))
A19: =IF(DANH_MUC!A13="","",DANH_MUC!A13) | B19: =IF(A19="","",COUNTIF(CONG_VIEC!$D$6:$D$305,A19)) | C19: =IF(A19="","",B19-COUNTIFS(CONG_VIEC!$D$6:$D$305,A19,CONG_VIEC!$K$6:$K$305,"Hoàn thành")) | D19: =IF(A19="","",COUNTIFS(CONG_VIEC!$D$6:$D$305,A19,CONG_VIEC!$P$6:$P$305,"Quá hạn")) | E19: =IF(A19="","",COUNTIFS(CONG_VIEC!$D$6:$D$305,A19,CONG_VIEC!$P$6:$P$305,"Sắp đến hạn")+COUNTIFS(CONG_VIEC!$D$6:$D$305,A19,CONG_VIEC!$P$6:$P$305,"Đến hạn hôm nay")) | F19: =IF(A19="","",COUNTIFS(CONG_VIEC!$D$6:$D$305,A19,CONG_VIEC!$K$6:$K$305,"Hoàn thành")) | G19: =IF(A19="","",COUNTIFS(CONG_VIEC!$D$6:$D$305,A19,CONG_VIEC!$P$6:$P$305,"Xong đúng hạn")) | H19: =IF(A19="","",COUNTIFS(CONG_VIEC!$D$6:$D$305,A19,CONG_VIEC!$P$6:$P$305,"Xong trễ")) | I19: =IF(A19="","",IFERROR(G19/(G19+H19),"-")) | J19: =IF(A19="","",IFERROR(F19/B19,"-"))
A20: =IF(DANH_MUC!A14="","",DANH_MUC!A14) | B20: =IF(A20="","",COUNTIF(CONG_VIEC!$D$6:$D$305,A20)) | C20: =IF(A20="","",B20-COUNTIFS(CONG_VIEC!$D$6:$D$305,A20,CONG_VIEC!$K$6:$K$305,"Hoàn thành")) | D20: =IF(A20="","",COUNTIFS(CONG_VIEC!$D$6:$D$305,A20,CONG_VIEC!$P$6:$P$305,"Quá hạn")) | E20: =IF(A20="","",COUNTIFS(CONG_VIEC!$D$6:$D$305,A20,CONG_VIEC!$P$6:$P$305,"Sắp đến hạn")+COUNTIFS(CONG_VIEC!$D$6:$D$305,A20,CONG_VIEC!$P$6:$P$305,"Đến hạn hôm nay")) | F20: =IF(A20="","",COUNTIFS(CONG_VIEC!$D$6:$D$305,A20,CONG_VIEC!$K$6:$K$305,"Hoàn thành")) | G20: =IF(A20="","",COUNTIFS(CONG_VIEC!$D$6:$D$305,A20,CONG_VIEC!$P$6:$P$305,"Xong đúng hạn")) | H20: =IF(A20="","",COUNTIFS(CONG_VIEC!$D$6:$D$305,A20,CONG_VIEC!$P$6:$P$305,"Xong trễ")) | I20: =IF(A20="","",IFERROR(G20/(G20+H20),"-")) | J20: =IF(A20="","",IFERROR(F20/B20,"-"))
A22: KPI CÁ NHÂN THEO NGƯỜI PHỤ TRÁCH
A23: Người phụ trách | B23: Tổng việc | C23: Đang mở | D23: Quá hạn | E23: Sắp đến hạn | F23: Hoàn thành | G23: Xong đúng hạn | H23: Xong trễ | I23: Tỷ lệ đúng hạn | J23: Tỷ lệ hoàn thành
A24: =IF(DANH_MUC!C5="","",DANH_MUC!C5) -> Người 1 (sửa tên) | B24: =IF(A24="","",COUNTIF(CONG_VIEC!$F$6:$F$305,A24)) -> 2 | C24: =IF(A24="","",B24-COUNTIFS(CONG_VIEC!$F$6:$F$305,A24,CONG_VIEC!$K$6:$K$305,"Hoàn thành")) -> 1 | D24: =IF(A24="","",COUNTIFS(CONG_VIEC!$F$6:$F$305,A24,CONG_VIEC!$P$6:$P$305,"Quá hạn")) -> 1 | E24: =IF(A24="","",COUNTIFS(CONG_VIEC!$F$6:$F$305,A24,CONG_VIEC!$P$6:$P$305,"Sắp đến hạn")+COUNTIFS(CONG_VIEC!$F$6:$F$305,A24,CONG_VIEC!$P$6:$P$305,"Đến hạn hôm nay")) -> 0 | F24: =IF(A24="","",COUNTIFS(CONG_VIEC!$F$6:$F$305,A24,CONG_VIEC!$K$6:$K$305,"Hoàn thành")) -> 1 | G24: =IF(A24="","",COUNTIFS(CONG_VIEC!$F$6:$F$305,A24,CONG_VIEC!$P$6:$P$305,"Xong đúng hạn")) -> 1 | H24: =IF(A24="","",COUNTIFS(CONG_VIEC!$F$6:$F$305,A24,CONG_VIEC!$P$6:$P$305,"Xong trễ")) -> 0 | I24: =IF(A24="","",IFERROR(G24/(G24+H24),"-")) -> 1 | J24: =IF(A24="","",IFERROR(F24/B24,"-")) -> 0.5
A25: =IF(DANH_MUC!C6="","",DANH_MUC!C6) -> Người 2 (sửa tên) | B25: =IF(A25="","",COUNTIF(CONG_VIEC!$F$6:$F$305,A25)) -> 1 | C25: =IF(A25="","",B25-COUNTIFS(CONG_VIEC!$F$6:$F$305,A25,CONG_VIEC!$K$6:$K$305,"Hoàn thành")) -> 1 | D25: =IF(A25="","",COUNTIFS(CONG_VIEC!$F$6:$F$305,A25,CONG_VIEC!$P$6:$P$305,"Quá hạn")) -> 0 | E25: =IF(A25="","",COUNTIFS(CONG_VIEC!$F$6:$F$305,A25,CONG_VIEC!$P$6:$P$305,"Sắp đến hạn")+COUNTIFS(CONG_VIEC!$F$6:$F$305,A25,CONG_VIEC!$P$6:$P$305,"Đến hạn hôm nay")) -> 1 | F25: =IF(A25="","",COUNTIFS(CONG_VIEC!$F$6:$F$305,A25,CONG_VIEC!$K$6:$K$305,"Hoàn thành")) -> 0 | G25: =IF(A25="","",COUNTIFS(CONG_VIEC!$F$6:$F$305,A25,CONG_VIEC!$P$6:$P$305,"Xong đúng hạn")) -> 0 | H25: =IF(A25="","",COUNTIFS(CONG_VIEC!$F$6:$F$305,A25,CONG_VIEC!$P$6:$P$305,"Xong trễ")) -> 0 | I25: =IF(A25="","",IFERROR(G25/(G25+H25),"-")) -> - | J25: =IF(A25="","",IFERROR(F25/B25,"-")) -> 0
A26: =IF(DANH_MUC!C7="","",DANH_MUC!C7) -> Người 3 (sửa tên) | B26: =IF(A26="","",COUNTIF(CONG_VIEC!$F$6:$F$305,A26)) -> 1 | C26: =IF(A26="","",B26-COUNTIFS(CONG_VIEC!$F$6:$F$305,A26,CONG_VIEC!$K$6:$K$305,"Hoàn thành")) -> 1 | D26: =IF(A26="","",COUNTIFS(CONG_VIEC!$F$6:$F$305,A26,CONG_VIEC!$P$6:$P$305,"Quá hạn")) -> 0 | E26: =IF(A26="","",COUNTIFS(CONG_VIEC!$F$6:$F$305,A26,CONG_VIEC!$P$6:$P$305,"Sắp đến hạn")+COUNTIFS(CONG_VIEC!$F$6:$F$305,A26,CONG_VIEC!$P$6:$P$305,"Đến hạn hôm nay")) -> 1 | F26: =IF(A26="","",COUNTIFS(CONG_VIEC!$F$6:$F$305,A26,CONG_VIEC!$K$6:$K$305,"Hoàn thành")) -> 0 | G26: =IF(A26="","",COUNTIFS(CONG_VIEC!$F$6:$F$305,A26,CONG_VIEC!$P$6:$P$305,"Xong đúng hạn")) -> 0 | H26: =IF(A26="","",COUNTIFS(CONG_VIEC!$F$6:$F$305,A26,CONG_VIEC!$P$6:$P$305,"Xong trễ")) -> 0 | I26: =IF(A26="","",IFERROR(G26/(G26+H26),"-")) -> - | J26: =IF(A26="","",IFERROR(F26/B26,"-")) -> 0
A27: =IF(DANH_MUC!C8="","",DANH_MUC!C8) -> Người 4 (sửa tên) | B27: =IF(A27="","",COUNTIF(CONG_VIEC!$F$6:$F$305,A27)) -> 1 | C27: =IF(A27="","",B27-COUNTIFS(CONG_VIEC!$F$6:$F$305,A27,CONG_VIEC!$K$6:$K$305,"Hoàn thành")) -> 1 | D27: =IF(A27="","",COUNTIFS(CONG_VIEC!$F$6:$F$305,A27,CONG_VIEC!$P$6:$P$305,"Quá hạn")) -> 0 | E27: =IF(A27="","",COUNTIFS(CONG_VIEC!$F$6:$F$305,A27,CONG_VIEC!$P$6:$P$305,"Sắp đến hạn")+COUNTIFS(CONG_VIEC!$F$6:$F$305,A27,CONG_VIEC!$P$6:$P$305,"Đến hạn hôm nay")) -> 0 | F27: =IF(A27="","",COUNTIFS(CONG_VIEC!$F$6:$F$305,A27,CONG_VIEC!$K$6:$K$305,"Hoàn thành")) -> 0 | G27: =IF(A27="","",COUNTIFS(CONG_VIEC!$F$6:$F$305,A27,CONG_VIEC!$P$6:$P$305,"Xong đúng hạn")) -> 0 | H27: =IF(A27="","",COUNTIFS(CONG_VIEC!$F$6:$F$305,A27,CONG_VIEC!$P$6:$P$305,"Xong trễ")) -> 0 | I27: =IF(A27="","",IFERROR(G27/(G27+H27),"-")) -> - | J27: =IF(A27="","",IFERROR(F27/B27,"-")) -> 0
A28: =IF(DANH_MUC!C9="","",DANH_MUC!C9) -> Người 5 (sửa tên) | B28: =IF(A28="","",COUNTIF(CONG_VIEC!$F$6:$F$305,A28)) -> 0 | C28: =IF(A28="","",B28-COUNTIFS(CONG_VIEC!$F$6:$F$305,A28,CONG_VIEC!$K$6:$K$305,"Hoàn thành")) -> 0 | D28: =IF(A28="","",COUNTIFS(CONG_VIEC!$F$6:$F$305,A28,CONG_VIEC!$P$6:$P$305,"Quá hạn")) -> 0 | E28: =IF(A28="","",COUNTIFS(CONG_VIEC!$F$6:$F$305,A28,CONG_VIEC!$P$6:$P$305,"Sắp đến hạn")+COUNTIFS(CONG_VIEC!$F$6:$F$305,A28,CONG_VIEC!$P$6:$P$305,"Đến hạn hôm nay")) -> 0 | F28: =IF(A28="","",COUNTIFS(CONG_VIEC!$F$6:$F$305,A28,CONG_VIEC!$K$6:$K$305,"Hoàn thành")) -> 0 | G28: =IF(A28="","",COUNTIFS(CONG_VIEC!$F$6:$F$305,A28,CONG_VIEC!$P$6:$P$305,"Xong đúng hạn")) -> 0 | H28: =IF(A28="","",COUNTIFS(CONG_VIEC!$F$6:$F$305,A28,CONG_VIEC!$P$6:$P$305,"Xong trễ")) -> 0 | I28: =IF(A28="","",IFERROR(G28/(G28+H28),"-")) -> - | J28: =IF(A28="","",IFERROR(F28/B28,"-")) -> -
A29: =IF(DANH_MUC!C10="","",DANH_MUC!C10) -> Người 6 (sửa tên) | B29: =IF(A29="","",COUNTIF(CONG_VIEC!$F$6:$F$305,A29)) -> 0 | C29: =IF(A29="","",B29-COUNTIFS(CONG_VIEC!$F$6:$F$305,A29,CONG_VIEC!$K$6:$K$305,"Hoàn thành")) -> 0 | D29: =IF(A29="","",COUNTIFS(CONG_VIEC!$F$6:$F$305,A29,CONG_VIEC!$P$6:$P$305,"Quá hạn")) -> 0 | E29: =IF(A29="","",COUNTIFS(CONG_VIEC!$F$6:$F$305,A29,CONG_VIEC!$P$6:$P$305,"Sắp đến hạn")+COUNTIFS(CONG_VIEC!$F$6:$F$305,A29,CONG_VIEC!$P$6:$P$305,"Đến hạn hôm nay")) -> 0 | F29: =IF(A29="","",COUNTIFS(CONG_VIEC!$F$6:$F$305,A29,CONG_VIEC!$K$6:$K$305,"Hoàn thành")) -> 0 | G29: =IF(A29="","",COUNTIFS(CONG_VIEC!$F$6:$F$305,A29,CONG_VIEC!$P$6:$P$305,"Xong đúng hạn")) -> 0 | H29: =IF(A29="","",COUNTIFS(CONG_VIEC!$F$6:$F$305,A29,CONG_VIEC!$P$6:$P$305,"Xong trễ")) -> 0 | I29: =IF(A29="","",IFERROR(G29/(G29+H29),"-")) -> - | J29: =IF(A29="","",IFERROR(F29/B29,"-")) -> -
A30: =IF(DANH_MUC!C11="","",DANH_MUC!C11) -> Người 7 (sửa tên) | B30: =IF(A30="","",COUNTIF(CONG_VIEC!$F$6:$F$305,A30)) -> 0 | C30: =IF(A30="","",B30-COUNTIFS(CONG_VIEC!$F$6:$F$305,A30,CONG_VIEC!$K$6:$K$305,"Hoàn thành")) -> 0 | D30: =IF(A30="","",COUNTIFS(CONG_VIEC!$F$6:$F$305,A30,CONG_VIEC!$P$6:$P$305,"Quá hạn")) -> 0 | E30: =IF(A30="","",COUNTIFS(CONG_VIEC!$F$6:$F$305,A30,CONG_VIEC!$P$6:$P$305,"Sắp đến hạn")+COUNTIFS(CONG_VIEC!$F$6:$F$305,A30,CONG_VIEC!$P$6:$P$305,"Đến hạn hôm nay")) -> 0 | F30: =IF(A30="","",COUNTIFS(CONG_VIEC!$F$6:$F$305,A30,CONG_VIEC!$K$6:$K$305,"Hoàn thành")) -> 0 | G30: =IF(A30="","",COUNTIFS(CONG_VIEC!$F$6:$F$305,A30,CONG_VIEC!$P$6:$P$305,"Xong đúng hạn")) -> 0 | H30: =IF(A30="","",COUNTIFS(CONG_VIEC!$F$6:$F$305,A30,CONG_VIEC!$P$6:$P$305,"Xong trễ")) -> 0 | I30: =IF(A30="","",IFERROR(G30/(G30+H30),"-")) -> - | J30: =IF(A30="","",IFERROR(F30/B30,"-")) -> -
A31: =IF(DANH_MUC!C12="","",DANH_MUC!C12) -> Người 8 (sửa tên) | B31: =IF(A31="","",COUNTIF(CONG_VIEC!$F$6:$F$305,A31)) -> 0 | C31: =IF(A31="","",B31-COUNTIFS(CONG_VIEC!$F$6:$F$305,A31,CONG_VIEC!$K$6:$K$305,"Hoàn thành")) -> 0 | D31: =IF(A31="","",COUNTIFS(CONG_VIEC!$F$6:$F$305,A31,CONG_VIEC!$P$6:$P$305,"Quá hạn")) -> 0 | E31: =IF(A31="","",COUNTIFS(CONG_VIEC!$F$6:$F$305,A31,CONG_VIEC!$P$6:$P$305,"Sắp đến hạn")+COUNTIFS(CONG_VIEC!$F$6:$F$305,A31,CONG_VIEC!$P$6:$P$305,"Đến hạn hôm nay")) -> 0 | F31: =IF(A31="","",COUNTIFS(CONG_VIEC!$F$6:$F$305,A31,CONG_VIEC!$K$6:$K$305,"Hoàn thành")) -> 0 | G31: =IF(A31="","",COUNTIFS(CONG_VIEC!$F$6:$F$305,A31,CONG_VIEC!$P$6:$P$305,"Xong đúng hạn")) -> 0 | H31: =IF(A31="","",COUNTIFS(CONG_VIEC!$F$6:$F$305,A31,CONG_VIEC!$P$6:$P$305,"Xong trễ")) -> 0 | I31: =IF(A31="","",IFERROR(G31/(G31+H31),"-")) -> - | J31: =IF(A31="","",IFERROR(F31/B31,"-")) -> -
A32: =IF(DANH_MUC!C13="","",DANH_MUC!C13) | B32: =IF(A32="","",COUNTIF(CONG_VIEC!$F$6:$F$305,A32)) | C32: =IF(A32="","",B32-COUNTIFS(CONG_VIEC!$F$6:$F$305,A32,CONG_VIEC!$K$6:$K$305,"Hoàn thành")) | D32: =IF(A32="","",COUNTIFS(CONG_VIEC!$F$6:$F$305,A32,CONG_VIEC!$P$6:$P$305,"Quá hạn")) | E32: =IF(A32="","",COUNTIFS(CONG_VIEC!$F$6:$F$305,A32,CONG_VIEC!$P$6:$P$305,"Sắp đến hạn")+COUNTIFS(CONG_VIEC!$F$6:$F$305,A32,CONG_VIEC!$P$6:$P$305,"Đến hạn hôm nay")) | F32: =IF(A32="","",COUNTIFS(CONG_VIEC!$F$6:$F$305,A32,CONG_VIEC!$K$6:$K$305,"Hoàn thành")) | G32: =IF(A32="","",COUNTIFS(CONG_VIEC!$F$6:$F$305,A32,CONG_VIEC!$P$6:$P$305,"Xong đúng hạn")) | H32: =IF(A32="","",COUNTIFS(CONG_VIEC!$F$6:$F$305,A32,CONG_VIEC!$P$6:$P$305,"Xong trễ")) | I32: =IF(A32="","",IFERROR(G32/(G32+H32),"-")) | J32: =IF(A32="","",IFERROR(F32/B32,"-"))
A33: =IF(DANH_MUC!C14="","",DANH_MUC!C14) | B33: =IF(A33="","",COUNTIF(CONG_VIEC!$F$6:$F$305,A33)) | C33: =IF(A33="","",B33-COUNTIFS(CONG_VIEC!$F$6:$F$305,A33,CONG_VIEC!$K$6:$K$305,"Hoàn thành")) | D33: =IF(A33="","",COUNTIFS(CONG_VIEC!$F$6:$F$305,A33,CONG_VIEC!$P$6:$P$305,"Quá hạn")) | E33: =IF(A33="","",COUNTIFS(CONG_VIEC!$F$6:$F$305,A33,CONG_VIEC!$P$6:$P$305,"Sắp đến hạn")+COUNTIFS(CONG_VIEC!$F$6:$F$305,A33,CONG_VIEC!$P$6:$P$305,"Đến hạn hôm nay")) | F33: =IF(A33="","",COUNTIFS(CONG_VIEC!$F$6:$F$305,A33,CONG_VIEC!$K$6:$K$305,"Hoàn thành")) | G33: =IF(A33="","",COUNTIFS(CONG_VIEC!$F$6:$F$305,A33,CONG_VIEC!$P$6:$P$305,"Xong đúng hạn")) | H33: =IF(A33="","",COUNTIFS(CONG_VIEC!$F$6:$F$305,A33,CONG_VIEC!$P$6:$P$305,"Xong trễ")) | I33: =IF(A33="","",IFERROR(G33/(G33+H33),"-")) | J33: =IF(A33="","",IFERROR(F33/B33,"-"))
A34: =IF(DANH_MUC!C15="","",DANH_MUC!C15) | B34: =IF(A34="","",COUNTIF(CONG_VIEC!$F$6:$F$305,A34)) | C34: =IF(A34="","",B34-COUNTIFS(CONG_VIEC!$F$6:$F$305,A34,CONG_VIEC!$K$6:$K$305,"Hoàn thành")) | D34: =IF(A34="","",COUNTIFS(CONG_VIEC!$F$6:$F$305,A34,CONG_VIEC!$P$6:$P$305,"Quá hạn")) | E34: =IF(A34="","",COUNTIFS(CONG_VIEC!$F$6:$F$305,A34,CONG_VIEC!$P$6:$P$305,"Sắp đến hạn")+COUNTIFS(CONG_VIEC!$F$6:$F$305,A34,CONG_VIEC!$P$6:$P$305,"Đến hạn hôm nay")) | F34: =IF(A34="","",COUNTIFS(CONG_VIEC!$F$6:$F$305,A34,CONG_VIEC!$K$6:$K$305,"Hoàn thành")) | G34: =IF(A34="","",COUNTIFS(CONG_VIEC!$F$6:$F$305,A34,CONG_VIEC!$P$6:$P$305,"Xong đúng hạn")) | H34: =IF(A34="","",COUNTIFS(CONG_VIEC!$F$6:$F$305,A34,CONG_VIEC!$P$6:$P$305,"Xong trễ")) | I34: =IF(A34="","",IFERROR(G34/(G34+H34),"-")) | J34: =IF(A34="","",IFERROR(F34/B34,"-"))
A35: =IF(DANH_MUC!C16="","",DANH_MUC!C16) | B35: =IF(A35="","",COUNTIF(CONG_VIEC!$F$6:$F$305,A35)) | C35: =IF(A35="","",B35-COUNTIFS(CONG_VIEC!$F$6:$F$305,A35,CONG_VIEC!$K$6:$K$305,"Hoàn thành")) | D35: =IF(A35="","",COUNTIFS(CONG_VIEC!$F$6:$F$305,A35,CONG_VIEC!$P$6:$P$305,"Quá hạn")) | E35: =IF(A35="","",COUNTIFS(CONG_VIEC!$F$6:$F$305,A35,CONG_VIEC!$P$6:$P$305,"Sắp đến hạn")+COUNTIFS(CONG_VIEC!$F$6:$F$305,A35,CONG_VIEC!$P$6:$P$305,"Đến hạn hôm nay")) | F35: =IF(A35="","",COUNTIFS(CONG_VIEC!$F$6:$F$305,A35,CONG_VIEC!$K$6:$K$305,"Hoàn thành")) | G35: =IF(A35="","",COUNTIFS(CONG_VIEC!$F$6:$F$305,A35,CONG_VIEC!$P$6:$P$305,"Xong đúng hạn")) | H35: =IF(A35="","",COUNTIFS(CONG_VIEC!$F$6:$F$305,A35,CONG_VIEC!$P$6:$P$305,"Xong trễ")) | I35: =IF(A35="","",IFERROR(G35/(G35+H35),"-")) | J35: =IF(A35="","",IFERROR(F35/B35,"-"))
... A43: =IF(DANH_MUC!C24="","",DANH_MUC!C24) | B43: =IF(A43="","",COUNTIF(CONG_VIEC!$F$6:$F$305,A43)) | C43: =IF(A43="","",B43-COUNTIFS(CONG_VIEC!$F$6:$F$305,A43,CONG_VIEC!$K$6:$K$305,"Hoàn thành")) | D43: =IF(A43="","",COUNTIFS(CONG_VIEC!$F$6:$F$305,A43,CONG_VIEC!$P$6:$P$305,"Quá hạn")) | E43: =IF(A43="","",COUNTIFS(CONG_VIEC!$F$6:$F$305,A43,CONG_VIEC!$P$6:$P$305,"Sắp đến hạn")+COUNTIFS(CONG_VIEC!$F$6:$F$305,A43,CONG_VIEC!$P$6:$P$305,"Đến hạn hôm nay")) | F43: =IF(A43="","",COUNTIFS(CONG_VIEC!$F$6:$F$305,A43,CONG_VIEC!$K$6:$K$305,"Hoàn thành")) | G43: =IF(A43="","",COUNTIFS(CONG_VIEC!$F$6:$F$305,A43,CONG_VIEC!$P$6:$P$305,"Xong đúng hạn")) | H43: =IF(A43="","",COUNTIFS(CONG_VIEC!$F$6:$F$305,A43,CONG_VIEC!$P$6:$P$305,"Xong trễ")) | I43: =IF(A43="","",IFERROR(G43/(G43+H43),"-")) | J43: =IF(A43="","",IFERROR(F43/B43,"-"))

Sheet HOM_NAY
A1: VIỆC HÔM NAY — dùng giao ban đầu giờ
A2: Gồm việc QUÁ HẠN + việc ĐẾN HẠN HÔM NAY chưa hoàn thành. Xếp theo thứ tự dòng nhập.
A3: Hôm nay: | B3: =TODAY() -> 46288 | D3: Số việc: | E3: =COUNT(CONG_VIEC!$S$6:$S$305) -> 2
A5: # | B5: Mã | C5: Tên công việc | D5: Đơn vị | E5: Người phụ trách | F5: Hạn | G5: Còn (ngày) | H5: Trạng thái | I5: Tình trạng hạn
A6: 1 | B6: =IFERROR(INDEX(CONG_VIEC!$A$6:$A$305,MATCH(A6,CONG_VIEC!$S$6:$S$305,0))&"","") -> CV001 | C6: =IFERROR(INDEX(CONG_VIEC!$C$6:$C$305,MATCH(A6,CONG_VIEC!$S$6:$S$305,0))&"","") -> [VÍ DỤ] Thu gom rác tồn đọng tuyến phố chính | D6: =IFERROR(INDEX(CONG_VIEC!$D$6:$D$305,MATCH(A6,CONG_VIEC!$S$6:$S$305,0))&"","") -> Đơn vị 1 (sửa tên) | E6: =IFERROR(INDEX(CONG_VIEC!$F$6:$F$305,MATCH(A6,CONG_VIEC!$S$6:$S$305,0))&"","") -> Người 1 (sửa tên) | F6: =IFERROR(INDEX(CONG_VIEC!$J$6:$J$305,MATCH(A6,CONG_VIEC!$S$6:$S$305,0)),"") -> 46286 | G6: =IFERROR(INDEX(CONG_VIEC!$O$6:$O$305,MATCH(A6,CONG_VIEC!$S$6:$S$305,0)),"") -> -2 | H6: =IFERROR(INDEX(CONG_VIEC!$K$6:$K$305,MATCH(A6,CONG_VIEC!$S$6:$S$305,0))&"","") -> Đang làm | I6: =IFERROR(INDEX(CONG_VIEC!$P$6:$P$305,MATCH(A6,CONG_VIEC!$S$6:$S$305,0))&"","") -> Quá hạn
A7: 2 | B7: =IFERROR(INDEX(CONG_VIEC!$A$6:$A$305,MATCH(A7,CONG_VIEC!$S$6:$S$305,0))&"","") -> CV002 | C7: =IFERROR(INDEX(CONG_VIEC!$C$6:$C$305,MATCH(A7,CONG_VIEC!$S$6:$S$305,0))&"","") -> [VÍ DỤ] Báo cáo tiến độ vệ sinh môi trường tháng 9 | D7: =IFERROR(INDEX(CONG_VIEC!$D$6:$D$305,MATCH(A7,CONG_VIEC!$S$6:$S$305,0))&"","") -> Đơn vị 2 (sửa tên) | E7: =IFERROR(INDEX(CONG_VIEC!$F$6:$F$305,MATCH(A7,CONG_VIEC!$S$6:$S$305,0))&"","") -> Người 2 (sửa tên) | F7: =IFERROR(INDEX(CONG_VIEC!$J$6:$J$305,MATCH(A7,CONG_VIEC!$S$6:$S$305,0)),"") -> 46288 | G7: =IFERROR(INDEX(CONG_VIEC!$O$6:$O$305,MATCH(A7,CONG_VIEC!$S$6:$S$305,0)),"") -> 0 | H7: =IFERROR(INDEX(CONG_VIEC!$K$6:$K$305,MATCH(A7,CONG_VIEC!$S$6:$S$305,0))&"","") -> Chưa làm | I7: =IFERROR(INDEX(CONG_VIEC!$P$6:$P$305,MATCH(A7,CONG_VIEC!$S$6:$S$305,0))&"","") -> Đến hạn hôm nay
A8: 3 | B8: =IFERROR(INDEX(CONG_VIEC!$A$6:$A$305,MATCH(A8,CONG_VIEC!$S$6:$S$305,0))&"","") | C8: =IFERROR(INDEX(CONG_VIEC!$C$6:$C$305,MATCH(A8,CONG_VIEC!$S$6:$S$305,0))&"","") | D8: =IFERROR(INDEX(CONG_VIEC!$D$6:$D$305,MATCH(A8,CONG_VIEC!$S$6:$S$305,0))&"","") | E8: =IFERROR(INDEX(CONG_VIEC!$F$6:$F$305,MATCH(A8,CONG_VIEC!$S$6:$S$305,0))&"","") | F8: =IFERROR(INDEX(CONG_VIEC!$J$6:$J$305,MATCH(A8,CONG_VIEC!$S$6:$S$305,0)),"") | G8: =IFERROR(INDEX(CONG_VIEC!$O$6:$O$305,MATCH(A8,CONG_VIEC!$S$6:$S$305,0)),"") | H8: =IFERROR(INDEX(CONG_VIEC!$K$6:$K$305,MATCH(A8,CONG_VIEC!$S$6:$S$305,0))&"","") | I8: =IFERROR(INDEX(CONG_VIEC!$P$6:$P$305,MATCH(A8,CONG_VIEC!$S$6:$S$305,0))&"","")
A9: 4 | B9: =IFERROR(INDEX(CONG_VIEC!$A$6:$A$305,MATCH(A9,CONG_VIEC!$S$6:$S$305,0))&"","") | C9: =IFERROR(INDEX(CONG_VIEC!$C$6:$C$305,MATCH(A9,CONG_VIEC!$S$6:$S$305,0))&"","") | D9: =IFERROR(INDEX(CONG_VIEC!$D$6:$D$305,MATCH(A9,CONG_VIEC!$S$6:$S$305,0))&"","") | E9: =IFERROR(INDEX(CONG_VIEC!$F$6:$F$305,MATCH(A9,CONG_VIEC!$S$6:$S$305,0))&"","") | F9: =IFERROR(INDEX(CONG_VIEC!$J$6:$J$305,MATCH(A9,CONG_VIEC!$S$6:$S$305,0)),"") | G9: =IFERROR(INDEX(CONG_VIEC!$O$6:$O$305,MATCH(A9,CONG_VIEC!$S$6:$S$305,0)),"") | H9: =IFERROR(INDEX(CONG_VIEC!$K$6:$K$305,MATCH(A9,CONG_VIEC!$S$6:$S$305,0))&"","") | I9: =IFERROR(INDEX(CONG_VIEC!$P$6:$P$305,MATCH(A9,CONG_VIEC!$S$6:$S$305,0))&"","")
A10: 5 | B10: =IFERROR(INDEX(CONG_VIEC!$A$6:$A$305,MATCH(A10,CONG_VIEC!$S$6:$S$305,0))&"","") | C10: =IFERROR(INDEX(CONG_VIEC!$C$6:$C$305,MATCH(A10,CONG_VIEC!$S$6:$S$305,0))&"","") | D10: =IFERROR(INDEX(CONG_VIEC!$D$6:$D$305,MATCH(A10,CONG_VIEC!$S$6:$S$305,0))&"","") | E10: =IFERROR(INDEX(CONG_VIEC!$F$6:$F$305,MATCH(A10,CONG_VIEC!$S$6:$S$305,0))&"","") | F10: =IFERROR(INDEX(CONG_VIEC!$J$6:$J$305,MATCH(A10,CONG_VIEC!$S$6:$S$305,0)),"") | G10: =IFERROR(INDEX(CONG_VIEC!$O$6:$O$305,MATCH(A10,CONG_VIEC!$S$6:$S$305,0)),"") | H10: =IFERROR(INDEX(CONG_VIEC!$K$6:$K$305,MATCH(A10,CONG_VIEC!$S$6:$S$305,0))&"","") | I10: =IFERROR(INDEX(CONG_VIEC!$P$6:$P$305,MATCH(A10,CONG_VIEC!$S$6:$S$305,0))&"","")
A11: 6 | B11: =IFERROR(INDEX(CONG_VIEC!$A$6:$A$305,MATCH(A11,CONG_VIEC!$S$6:$S$305,0))&"","") | C11: =IFERROR(INDEX(CONG_VIEC!$C$6:$C$305,MATCH(A11,CONG_VIEC!$S$6:$S$305,0))&"","") | D11: =IFERROR(INDEX(CONG_VIEC!$D$6:$D$305,MATCH(A11,CONG_VIEC!$S$6:$S$305,0))&"","") | E11: =IFERROR(INDEX(CONG_VIEC!$F$6:$F$305,MATCH(A11,CONG_VIEC!$S$6:$S$305,0))&"","") | F11: =IFERROR(INDEX(CONG_VIEC!$J$6:$J$305,MATCH(A11,CONG_VIEC!$S$6:$S$305,0)),"") | G11: =IFERROR(INDEX(CONG_VIEC!$O$6:$O$305,MATCH(A11,CONG_VIEC!$S$6:$S$305,0)),"") | H11: =IFERROR(INDEX(CONG_VIEC!$K$6:$K$305,MATCH(A11,CONG_VIEC!$S$6:$S$305,0))&"","") | I11: =IFERROR(INDEX(CONG_VIEC!$P$6:$P$305,MATCH(A11,CONG_VIEC!$S$6:$S$305,0))&"","")
A12: 7 | B12: =IFERROR(INDEX(CONG_VIEC!$A$6:$A$305,MATCH(A12,CONG_VIEC!$S$6:$S$305,0))&"","") | C12: =IFERROR(INDEX(CONG_VIEC!$C$6:$C$305,MATCH(A12,CONG_VIEC!$S$6:$S$305,0))&"","") | D12: =IFERROR(INDEX(CONG_VIEC!$D$6:$D$305,MATCH(A12,CONG_VIEC!$S$6:$S$305,0))&"","") | E12: =IFERROR(INDEX(CONG_VIEC!$F$6:$F$305,MATCH(A12,CONG_VIEC!$S$6:$S$305,0))&"","") | F12: =IFERROR(INDEX(CONG_VIEC!$J$6:$J$305,MATCH(A12,CONG_VIEC!$S$6:$S$305,0)),"") | G12: =IFERROR(INDEX(CONG_VIEC!$O$6:$O$305,MATCH(A12,CONG_VIEC!$S$6:$S$305,0)),"") | H12: =IFERROR(INDEX(CONG_VIEC!$K$6:$K$305,MATCH(A12,CONG_VIEC!$S$6:$S$305,0))&"","") | I12: =IFERROR(INDEX(CONG_VIEC!$P$6:$P$305,MATCH(A12,CONG_VIEC!$S$6:$S$305,0))&"","")
A13: 8 | B13: =IFERROR(INDEX(CONG_VIEC!$A$6:$A$305,MATCH(A13,CONG_VIEC!$S$6:$S$305,0))&"","") | C13: =IFERROR(INDEX(CONG_VIEC!$C$6:$C$305,MATCH(A13,CONG_VIEC!$S$6:$S$305,0))&"","") | D13: =IFERROR(INDEX(CONG_VIEC!$D$6:$D$305,MATCH(A13,CONG_VIEC!$S$6:$S$305,0))&"","") | E13: =IFERROR(INDEX(CONG_VIEC!$F$6:$F$305,MATCH(A13,CONG_VIEC!$S$6:$S$305,0))&"","") | F13: =IFERROR(INDEX(CONG_VIEC!$J$6:$J$305,MATCH(A13,CONG_VIEC!$S$6:$S$305,0)),"") | G13: =IFERROR(INDEX(CONG_VIEC!$O$6:$O$305,MATCH(A13,CONG_VIEC!$S$6:$S$305,0)),"") | H13: =IFERROR(INDEX(CONG_VIEC!$K$6:$K$305,MATCH(A13,CONG_VIEC!$S$6:$S$305,0))&"","") | I13: =IFERROR(INDEX(CONG_VIEC!$P$6:$P$305,MATCH(A13,CONG_VIEC!$S$6:$S$305,0))&"","")
A14: 9 | B14: =IFERROR(INDEX(CONG_VIEC!$A$6:$A$305,MATCH(A14,CONG_VIEC!$S$6:$S$305,0))&"","") | C14: =IFERROR(INDEX(CONG_VIEC!$C$6:$C$305,MATCH(A14,CONG_VIEC!$S$6:$S$305,0))&"","") | D14: =IFERROR(INDEX(CONG_VIEC!$D$6:$D$305,MATCH(A14,CONG_VIEC!$S$6:$S$305,0))&"","") | E14: =IFERROR(INDEX(CONG_VIEC!$F$6:$F$305,MATCH(A14,CONG_VIEC!$S$6:$S$305,0))&"","") | F14: =IFERROR(INDEX(CONG_VIEC!$J$6:$J$305,MATCH(A14,CONG_VIEC!$S$6:$S$305,0)),"") | G14: =IFERROR(INDEX(CONG_VIEC!$O$6:$O$305,MATCH(A14,CONG_VIEC!$S$6:$S$305,0)),"") | H14: =IFERROR(INDEX(CONG_VIEC!$K$6:$K$305,MATCH(A14,CONG_VIEC!$S$6:$S$305,0))&"","") | I14: =IFERROR(INDEX(CONG_VIEC!$P$6:$P$305,MATCH(A14,CONG_VIEC!$S$6:$S$305,0))&"","")
A15: 10 | B15: =IFERROR(INDEX(CONG_VIEC!$A$6:$A$305,MATCH(A15,CONG_VIEC!$S$6:$S$305,0))&"","") | C15: =IFERROR(INDEX(CONG_VIEC!$C$6:$C$305,MATCH(A15,CONG_VIEC!$S$6:$S$305,0))&"","") | D15: =IFERROR(INDEX(CONG_VIEC!$D$6:$D$305,MATCH(A15,CONG_VIEC!$S$6:$S$305,0))&"","") | E15: =IFERROR(INDEX(CONG_VIEC!$F$6:$F$305,MATCH(A15,CONG_VIEC!$S$6:$S$305,0))&"","") | F15: =IFERROR(INDEX(CONG_VIEC!$J$6:$J$305,MATCH(A15,CONG_VIEC!$S$6:$S$305,0)),"") | G15: =IFERROR(INDEX(CONG_VIEC!$O$6:$O$305,MATCH(A15,CONG_VIEC!$S$6:$S$305,0)),"") | H15: =IFERROR(INDEX(CONG_VIEC!$K$6:$K$305,MATCH(A15,CONG_VIEC!$S$6:$S$305,0))&"","") | I15: =IFERROR(INDEX(CONG_VIEC!$P$6:$P$305,MATCH(A15,CONG_VIEC!$S$6:$S$305,0))&"","")
A16: 11 | B16: =IFERROR(INDEX(CONG_VIEC!$A$6:$A$305,MATCH(A16,CONG_VIEC!$S$6:$S$305,0))&"","") | C16: =IFERROR(INDEX(CONG_VIEC!$C$6:$C$305,MATCH(A16,CONG_VIEC!$S$6:$S$305,0))&"","") | D16: =IFERROR(INDEX(CONG_VIEC!$D$6:$D$305,MATCH(A16,CONG_VIEC!$S$6:$S$305,0))&"","") | E16: =IFERROR(INDEX(CONG_VIEC!$F$6:$F$305,MATCH(A16,CONG_VIEC!$S$6:$S$305,0))&"","") | F16: =IFERROR(INDEX(CONG_VIEC!$J$6:$J$305,MATCH(A16,CONG_VIEC!$S$6:$S$305,0)),"") | G16: =IFERROR(INDEX(CONG_VIEC!$O$6:$O$305,MATCH(A16,CONG_VIEC!$S$6:$S$305,0)),"") | H16: =IFERROR(INDEX(CONG_VIEC!$K$6:$K$305,MATCH(A16,CONG_VIEC!$S$6:$S$305,0))&"","") | I16: =IFERROR(INDEX(CONG_VIEC!$P$6:$P$305,MATCH(A16,CONG_VIEC!$S$6:$S$305,0))&"","")
A17: 12 | B17: =IFERROR(INDEX(CONG_VIEC!$A$6:$A$305,MATCH(A17,CONG_VIEC!$S$6:$S$305,0))&"","") | C17: =IFERROR(INDEX(CONG_VIEC!$C$6:$C$305,MATCH(A17,CONG_VIEC!$S$6:$S$305,0))&"","") | D17: =IFERROR(INDEX(CONG_VIEC!$D$6:$D$305,MATCH(A17,CONG_VIEC!$S$6:$S$305,0))&"","") | E17: =IFERROR(INDEX(CONG_VIEC!$F$6:$F$305,MATCH(A17,CONG_VIEC!$S$6:$S$305,0))&"","") | F17: =IFERROR(INDEX(CONG_VIEC!$J$6:$J$305,MATCH(A17,CONG_VIEC!$S$6:$S$305,0)),"") | G17: =IFERROR(INDEX(CONG_VIEC!$O$6:$O$305,MATCH(A17,CONG_VIEC!$S$6:$S$305,0)),"") | H17: =IFERROR(INDEX(CONG_VIEC!$K$6:$K$305,MATCH(A17,CONG_VIEC!$S$6:$S$305,0))&"","") | I17: =IFERROR(INDEX(CONG_VIEC!$P$6:$P$305,MATCH(A17,CONG_VIEC!$S$6:$S$305,0))&"","")
... A105: 100 | B105: =IFERROR(INDEX(CONG_VIEC!$A$6:$A$305,MATCH(A105,CONG_VIEC!$S$6:$S$305,0))&"","") | C105: =IFERROR(INDEX(CONG_VIEC!$C$6:$C$305,MATCH(A105,CONG_VIEC!$S$6:$S$305,0))&"","") | D105: =IFERROR(INDEX(CONG_VIEC!$D$6:$D$305,MATCH(A105,CONG_VIEC!$S$6:$S$305,0))&"","") | E105: =IFERROR(INDEX(CONG_VIEC!$F$6:$F$305,MATCH(A105,CONG_VIEC!$S$6:$S$305,0))&"","") | F105: =IFERROR(INDEX(CONG_VIEC!$J$6:$J$305,MATCH(A105,CONG_VIEC!$S$6:$S$305,0)),"") | G105: =IFERROR(INDEX(CONG_VIEC!$O$6:$O$305,MATCH(A105,CONG_VIEC!$S$6:$S$305,0)),"") | H105: =IFERROR(INDEX(CONG_VIEC!$K$6:$K$305,MATCH(A105,CONG_VIEC!$S$6:$S$305,0))&"","") | I105: =IFERROR(INDEX(CONG_VIEC!$P$6:$P$305,MATCH(A105,CONG_VIEC!$S$6:$S$305,0))&"","")

Sheet KANBAN
A1: BẢNG KANBAN — theo trạng thái
A2: Ô Trạng thái để trống được tính là 'Chưa làm'. Mỗi cột hiện tối đa 60 việc.
A4: ="CHƯA LÀM ("&COUNT(CONG_VIEC!$T$6:$T$305)&")" -> CHƯA LÀM (2) | F4: ="ĐANG LÀM ("&COUNT(CONG_VIEC!$U$6:$U$305)&")" -> ĐANG LÀM (1) | K4: ="CHỜ DUYỆT ("&COUNT(CONG_VIEC!$V$6:$V$305)&")" -> CHỜ DUYỆT (1) | P4: ="HOÀN THÀNH ("&COUNT(CONG_VIEC!$W$6:$W$305)&")" -> HOÀN THÀNH (1)
A5: # | B5: Tên công việc | C5: Người | D5: Hạn | F5: # | G5: Tên công việc | H5: Người | I5: Hạn | K5: # | L5: Tên công việc | M5: Người | N5: Hạn | P5: # | Q5: Tên công việc | R5: Người | S5: Hạn
A6: 1 | B6: =IFERROR(INDEX(CONG_VIEC!$C$6:$C$305,MATCH(A6,CONG_VIEC!$T$6:$T$305,0))&"","") -> [VÍ DỤ] Báo cáo tiến độ vệ sinh môi trường tháng 9 | C6: =IFERROR(INDEX(CONG_VIEC!$F$6:$F$305,MATCH(A6,CONG_VIEC!$T$6:$T$305,0))&"","") -> Người 2 (sửa tên) | D6: =IFERROR(INDEX(CONG_VIEC!$J$6:$J$305,MATCH(A6,CONG_VIEC!$T$6:$T$305,0)),"") -> 46288 | F6: 1 | G6: =IFERROR(INDEX(CONG_VIEC!$C$6:$C$305,MATCH(F6,CONG_VIEC!$U$6:$U$305,0))&"","") -> [VÍ DỤ] Thu gom rác tồn đọng tuyến phố chính | H6: =IFERROR(INDEX(CONG_VIEC!$F$6:$F$305,MATCH(F6,CONG_VIEC!$U$6:$U$305,0))&"","") -> Người 1 (sửa tên) | I6: =IFERROR(INDEX(CONG_VIEC!$J$6:$J$305,MATCH(F6,CONG_VIEC!$U$6:$U$305,0)),"") -> 46286 | K6: 1 | L6: =IFERROR(INDEX(CONG_VIEC!$C$6:$C$305,MATCH(K6,CONG_VIEC!$V$6:$V$305,0))&"","") -> [VÍ DỤ] Sửa nắp hố ga bị vỡ theo phản ánh | M6: =IFERROR(INDEX(CONG_VIEC!$F$6:$F$305,MATCH(K6,CONG_VIEC!$V$6:$V$305,0))&"","") -> Người 3 (sửa tên) | N6: =IFERROR(INDEX(CONG_VIEC!$J$6:$J$305,MATCH(K6,CONG_VIEC!$V$6:$V$305,0)),"") -> 46290 | P6: 1 | Q6: =IFERROR(INDEX(CONG_VIEC!$C$6:$C$305,MATCH(P6,CONG_VIEC!$W$6:$W$305,0))&"","") -> [VÍ DỤ] Phun rửa đường sau sự kiện | R6: =IFERROR(INDEX(CONG_VIEC!$F$6:$F$305,MATCH(P6,CONG_VIEC!$W$6:$W$305,0))&"","") -> Người 1 (sửa tên) | S6: =IFERROR(INDEX(CONG_VIEC!$J$6:$J$305,MATCH(P6,CONG_VIEC!$W$6:$W$305,0)),"") -> 46284
